Workbook

Sheet JUILLET
B4: ETAT DES SALAIRES KS SARL
B5: Période: | D5: 46204 | F5: Ventilation simulée (max. exonéré) | J5: Hypothèses | L5: Calcul IUTS | T5: TPA, Rosalaire et net
B6: N° | C6: Nom&Prénom | D6: DATE D'ENTREE | E6: 46204 | F6: Ind. Logement | G6: Ind. Transport | H6: Ind. Fonction | I6: Salaire de base | J6: Nb charges | K6: Catégorie | L6: Montant exonéré | M6: CNSS salarié 5,5 % | N6: Déduction retraite | O6: Abattement forfaitaire | P6: Base imposable (arr. 100) | Q6: IUTS brut | R6: Réduction charges | S6: IUTS NET | T6: TPA 3 % (patronale) | U6: Rosalaire 1 % | V6: SALAIRE NET À PAYER
B7: 1 | C7: BAGAGNAN Salima | D7: 46242 | E7: 0 | F7: =MIN(ROUNDDOWN(N($E7)*Paramètres!$C$16,0),Paramètres!$D$16) -> 0 | G7: =MIN(ROUNDDOWN(N($E7)*Paramètres!$C$17,0),Paramètres!$D$17) -> 0 | H7: =MIN(ROUNDDOWN(N($E7)*Paramètres!$C$18,0),Paramètres!$D$18) -> 0 | I7: =N($E7)-(F7+G7+H7) -> 0 | J7: 0 | K7: =IF(I7<Paramètres!$C$11,"Cadre inférieur","Cadre supérieur") -> Cadre inférieur | L7: =MIN(F7,MIN(N($E7)*Paramètres!$C$16,Paramètres!$D$16))+MIN(G7,MIN(N($E7)*Paramètres!$C$17,Paramètres!$D$17))+MIN(H7,MIN(N($E7)*Paramètres!$C$18,Paramètres!$D$18)) -> 0 | M7: =MIN(N($E7),Paramètres!$C$7)*Paramètres!$C$6 -> 0 | N7: =MIN(M7,I7*Paramètres!$C$8) -> 0 | O7: =I7*IF(K7="Cadre supérieur",Paramètres!$C$10,Paramètres!$C$9) -> 0 | P7: =MAX(0,ROUNDDOWN(N($E7)-L7-N7-O7,-2)) -> 0 | Q7: =SUMPRODUCT((P7>Paramètres!$B$21:$B$27)*(P7-Paramètres!$B$21:$B$27)*Paramètres!$E$21:$E$27) -> 0 | R7: =Q7*INDEX(Paramètres!$C$31:$C$38,MIN(MAX(INT(N(J7)),0),7)+1) -> 0 | S7: =ROUND(Q7-R7,0) -> 0 | T7: =ROUND(N($E7)*Paramètres!$C$13,0) -> 0 | U7: =ROUND(MAX(0,N($E7)-(Q7-R7)-M7)*Paramètres!$C$12,0) -> 0 | V7: =ROUND(N($E7)-M7-S7-U7,0) -> 0
B8: 2 | C8: BANHORO Adama | D8: 46196 | E8: 0 | F8: =MIN(ROUNDDOWN(N($E8)*Paramètres!$C$16,0),Paramètres!$D$16) -> 0 | G8: =MIN(ROUNDDOWN(N($E8)*Paramètres!$C$17,0),Paramètres!$D$17) -> 0 | H8: =MIN(ROUNDDOWN(N($E8)*Paramètres!$C$18,0),Paramètres!$D$18) -> 0 | I8: =N($E8)-(F8+G8+H8) -> 0 | J8: 0 | K8: =IF(I8<Paramètres!$C$11,"Cadre inférieur","Cadre supérieur") -> Cadre inférieur | L8: =MIN(F8,MIN(N($E8)*Paramètres!$C$16,Paramètres!$D$16))+MIN(G8,MIN(N($E8)*Paramètres!$C$17,Paramètres!$D$17))+MIN(H8,MIN(N($E8)*Paramètres!$C$18,Paramètres!$D$18)) -> 0 | M8: =MIN(N($E8),Paramètres!$C$7)*Paramètres!$C$6 -> 0 | N8: =MIN(M8,I8*Paramètres!$C$8) -> 0 | O8: =I8*IF(K8="Cadre supérieur",Paramètres!$C$10,Paramètres!$C$9) -> 0 | P8: =MAX(0,ROUNDDOWN(N($E8)-L8-N8-O8,-2)) -> 0 | Q8: =SUMPRODUCT((P8>Paramètres!$B$21:$B$27)*(P8-Paramètres!$B$21:$B$27)*Paramètres!$E$21:$E$27) -> 0 | R8: =Q8*INDEX(Paramètres!$C$31:$C$38,MIN(MAX(INT(N(J8)),0),7)+1) -> 0 | S8: =ROUND(Q8-R8,0) -> 0 | T8: =ROUND(N($E8)*Paramètres!$C$13,0) -> 0 | U8: =ROUND(MAX(0,N($E8)-(Q8-R8)-M8)*Paramètres!$C$12,0) -> 0 | V8: =ROUND(N($E8)-M8-S8-U8,0) -> 0
B9: 3 | C9: BARRO Yacouba | D9: 46000 | E9: 177387 | F9: =MIN(ROUNDDOWN(N($E9)*Paramètres!$C$16,0),Paramètres!$D$16) -> 35477 | G9: =MIN(ROUNDDOWN(N($E9)*Paramètres!$C$17,0),Paramètres!$D$17) -> 8869 | H9: =MIN(ROUNDDOWN(N($E9)*Paramètres!$C$18,0),Paramètres!$D$18) -> 8869 | I9: =N($E9)-(F9+G9+H9) -> 124172 | J9: 0 | K9: =IF(I9<Paramètres!$C$11,"Cadre inférieur","Cadre supérieur") -> Cadre inférieur | L9: =MIN(F9,MIN(N($E9)*Paramètres!$C$16,Paramètres!$D$16))+MIN(G9,MIN(N($E9)*Paramètres!$C$17,Paramètres!$D$17))+MIN(H9,MIN(N($E9)*Paramètres!$C$18,Paramètres!$D$18)) -> 53215 | M9: =MIN(N($E9),Paramètres!$C$7)*Paramètres!$C$6 -> 9756.285 | N9: =MIN(M9,I9*Paramètres!$C$8) -> 9756.285 | O9: =I9*IF(K9="Cadre supérieur",Paramètres!$C$10,Paramètres!$C$9) -> 31043 | P9: =MAX(0,ROUNDDOWN(N($E9)-L9-N9-O9,-2)) -> 83300 | Q9: =SUMPRODUCT((P9>Paramètres!$B$21:$B$27)*(P9-Paramètres!$B$21:$B$27)*Paramètres!$E$21:$E$27) -> 7108.1 | R9: =Q9*INDEX(Paramètres!$C$31:$C$38,MIN(MAX(INT(N(J9)),0),7)+1) -> 0 | S9: =ROUND(Q9-R9,0) -> 7108 | T9: =ROUND(N($E9)*Paramètres!$C$13,0) -> 5322 | U9: =ROUND(MAX(0,N($E9)-(Q9-R9)-M9)*Paramètres!$C$12,0) -> 1605 | V9: =ROUND(N($E9)-M9-S9-U9,0) -> 158918
B10: 4 | C10: BASSOLE Ines | D10: 45677 | E10: 346515 | F10: =MIN(ROUNDDOWN(N($E10)*Paramètres!$C$16,0),Paramètres!$D$16) -> 69303 | G10: =MIN(ROUNDDOWN(N($E10)*Paramètres!$C$17,0),Paramètres!$D$17) -> 17325 | H10: =MIN(ROUNDDOWN(N($E10)*Paramètres!$C$18,0),Paramètres!$D$18) -> 17325 | I10: =N($E10)-(F10+G10+H10) -> 242562 | J10: 0 | K10: =IF(I10<Paramètres!$C$11,"Cadre inférieur","Cadre supérieur") -> Cadre supérieur | L10: =MIN(F10,MIN(N($E10)*Paramètres!$C$16,Paramètres!$D$16))+MIN(G10,MIN(N($E10)*Paramètres!$C$17,Paramètres!$D$17))+MIN(H10,MIN(N($E10)*Paramètres!$C$18,Paramètres!$D$18)) -> 103953 | M10: =MIN(N($E10),Paramètres!$C$7)*Paramètres!$C$6 -> 19058.325 | N10: =MIN(M10,I10*Paramètres!$C$8) -> 19058.325 | O10: =I10*IF(K10="Cadre supérieur",Paramètres!$C$10,Paramètres!$C$9) -> 48512.4 | P10: =MAX(0,ROUNDDOWN(N($E10)-L10-N10-O10,-2)) -> 174900 | Q10: =SUMPRODUCT((P10>Paramètres!$B$21:$B$27)*(P10-Paramètres!$B$21:$B$27)*Paramètres!$E$21:$E$27) -> 23133.3 | R10: =Q10*INDEX(Paramètres!$C$31:$C$38,MIN(MAX(INT(N(J10)),0),7)+1) -> 0 | S10: =ROUND(Q10-R10,0) -> 23133 | T10: =ROUND(N($E10)*Paramètres!$C$13,0) -> 10395 | U10: =ROUND(MAX(0,N($E10)-(Q10-R10)-M10)*Paramètres!$C$12,0) -> 3043 | V10: =ROUND(N($E10)-M10-S10-U10,0) -> 301281
B11: 5 | C11: BAWAR B. Fulgence | D11: 46023 | E11: 165340 | F11: =MIN(ROUNDDOWN(N($E11)*Paramètres!$C$16,0),Paramètres!$D$16) -> 33068 | G11: =MIN(ROUNDDOWN(N($E11)*Paramètres!$C$17,0),Paramètres!$D$17) -> 8267 | H11: =MIN(ROUNDDOWN(N($E11)*Paramètres!$C$18,0),Paramètres!$D$18) -> 8267 | I11: =N($E11)-(F11+G11+H11) -> 115738 | J11: 0 | K11: =IF(I11<Paramètres!$C$11,"Cadre inférieur","Cadre supérieur") -> Cadre inférieur | L11: =MIN(F11,MIN(N($E11)*Paramètres!$C$16,Paramètres!$D$16))+MIN(G11,MIN(N($E11)*Paramètres!$C$17,Paramètres!$D$17))+MIN(H11,MIN(N($E11)*Paramètres!$C$18,Paramètres!$D$18)) -> 49602 | M11: =MIN(N($E11),Paramètres!$C$7)*Paramètres!$C$6 -> 9093.7 | N11: =MIN(M11,I11*Paramètres!$C$8) -> 9093.7 | O11: =I11*IF(K11="Cadre supérieur",Paramètres!$C$10,Paramètres!$C$9) -> 28934.5 | P11: =MAX(0,ROUNDDOWN(N($E11)-L11-N11-O11,-2)) -> 77700 | Q11: =SUMPRODUCT((P11>Paramètres!$B$21:$B$27)*(P11-Paramètres!$B$21:$B$27)*Paramètres!$E$21:$E$27) -> 6270.3 | R11: =Q11*INDEX(Paramètres!$C$31:$C$38,MIN(MAX(INT(N(J11)),0),7)+1) -> 0 | S11: =ROUND(Q11-R11,0) -> 6270 | T11: =ROUND(N($E11)*Paramètres!$C$13,0) -> 4960 | U11: =ROUND(MAX(0,N($E11)-(Q11-R11)-M11)*Paramètres!$C$12,0) -> 1500 | V11: =ROUND(N($E11)-M11-S11-U11,0) -> 148476
B12: 6 | C12: BAZIE Issouf | D12: 46217 | E12: 0 | F12: =MIN(ROUNDDOWN(N($E12)*Paramètres!$C$16,0),Paramètres!$D$16) -> 0 | G12: =MIN(ROUNDDOWN(N($E12)*Paramètres!$C$17,0),Paramètres!$D$17) -> 0 | H12: =MIN(ROUNDDOWN(N($E12)*Paramètres!$C$18,0),Paramètres!$D$18) -> 0 | I12: =N($E12)-(F12+G12+H12) -> 0 | J12: 0 | K12: =IF(I12<Paramètres!$C$11,"Cadre inférieur","Cadre supérieur") -> Cadre inférieur | L12: =MIN(F12,MIN(N($E12)*Paramètres!$C$16,Paramètres!$D$16))+MIN(G12,MIN(N($E12)*Paramètres!$C$17,Paramètres!$D$17))+MIN(H12,MIN(N($E12)*Paramètres!$C$18,Paramètres!$D$18)) -> 0 | M12: =MIN(N($E12),Paramètres!$C$7)*Paramètres!$C$6 -> 0 | N12: =MIN(M12,I12*Paramètres!$C$8) -> 0 | O12: =I12*IF(K12="Cadre supérieur",Paramètres!$C$10,Paramètres!$C$9) -> 0 | P12: =MAX(0,ROUNDDOWN(N($E12)-L12-N12-O12,-2)) -> 0 | Q12: =SUMPRODUCT((P12>Paramètres!$B$21:$B$27)*(P12-Paramètres!$B$21:$B$27)*Paramètres!$E$21:$E$27) -> 0 | R12: =Q12*INDEX(Paramètres!$C$31:$C$38,MIN(MAX(INT(N(J12)),0),7)+1) -> 0 | S12: =ROUND(Q12-R12,0) -> 0 | T12: =ROUND(N($E12)*Paramètres!$C$13,0) -> 0 | U12: =ROUND(MAX(0,N($E12)-(Q12-R12)-M12)*Paramètres!$C$12,0) -> 0 | V12: =ROUND(N($E12)-M12-S12-U12,0) -> 0
B13: 7 | C13: BELEM Abdoulaye | D13: 46174 | E13: 195484 | F13: =MIN(ROUNDDOWN(N($E13)*Paramètres!$C$16,0),Paramètres!$D$16) -> 39096 | G13: =MIN(ROUNDDOWN(N($E13)*Paramètres!$C$17,0),Paramètres!$D$17) -> 9774 | H13: =MIN(ROUNDDOWN(N($E13)*Paramètres!$C$18,0),Paramètres!$D$18) -> 9774 | I13: =N($E13)-(F13+G13+H13) -> 136840 | J13: 0 | K13: =IF(I13<Paramètres!$C$11,"Cadre inférieur","Cadre supérieur") -> Cadre inférieur | L13: =MIN(F13,MIN(N($E13)*Paramètres!$C$16,Paramètres!$D$16))+MIN(G13,MIN(N($E13)*Paramètres!$C$17,Paramètres!$D$17))+MIN(H13,MIN(N($E13)*Paramètres!$C$18,Paramètres!$D$18)) -> 58644 | M13: =MIN(N($E13),Paramètres!$C$7)*Paramètres!$C$6 -> 10751.62 | N13: =MIN(M13,I13*Paramètres!$C$8) -> 10751.62 | O13: =I13*IF(K13="Cadre supérieur",Paramètres!$C$10,Paramètres!$C$9) -> 34210 | P13: =MAX(0,ROUNDDOWN(N($E13)-L13-N13-O13,-2)) -> 91800 | Q13: =SUMPRODUCT((P13>Paramètres!$B$21:$B$27)*(P13-Paramètres!$B$21:$B$27)*Paramètres!$E$21:$E$27) -> 8442.6 | R13: =Q13*INDEX(Paramètres!$C$31:$C$38,MIN(MAX(INT(N(J13)),0),7)+1) -> 0 | S13: =ROUND(Q13-R13,0) -> 8443 | T13: =ROUND(N($E13)*Paramètres!$C$13,0) -> 5865 | U13: =ROUND(MAX(0,N($E13)-(Q13-R13)-M13)*Paramètres!$C$12,0) -> 1763 | V13: =ROUND(N($E13)-M13-S13-U13,0) -> 174526
B14: 8 | C14: BENAO Souleymane | D14: 45778 | E14: 213566 | F14: =MIN(ROUNDDOWN(N($E14)*Paramètres!$C$16,0),Paramètres!$D$16) -> 42713 | G14: =MIN(ROUNDDOWN(N($E14)*Paramètres!$C$17,0),Paramètres!$D$17) -> 10678 | H14: =MIN(ROUNDDOWN(N($E14)*Paramètres!$C$18,0),Paramètres!$D$18) -> 10678 | I14: =N($E14)-(F14+G14+H14) -> 149497 | J14: 0 | K14: =IF(I14<Paramètres!$C$11,"Cadre inférieur","Cadre supérieur") -> Cadre inférieur | L14: =MIN(F14,MIN(N($E14)*Paramètres!$C$16,Paramètres!$D$16))+MIN(G14,MIN(N($E14)*Paramètres!$C$17,Paramètres!$D$17))+MIN(H14,MIN(N($E14)*Paramètres!$C$18,Paramètres!$D$18)) -> 64069 | M14: =MIN(N($E14),Paramètres!$C$7)*Paramètres!$C$6 -> 11746.13 | N14: =MIN(M14,I14*Paramètres!$C$8) -> 11746.13 | O14: =I14*IF(K14="Cadre supérieur",Paramètres!$C$10,Paramètres!$C$9) -> 37374.25 | P14: =MAX(0,ROUNDDOWN(N($E14)-L14-N14-O14,-2)) -> 100300 | Q14: =SUMPRODUCT((P14>Paramètres!$B$21:$B$27)*(P14-Paramètres!$B$21:$B$27)*Paramètres!$E$21:$E$27) -> 9777.1 | R14: =Q14*INDEX(Paramètres!$C$31:$C$38,MIN(MAX(INT(N(J14)),0),7)+1) -> 0 | S14: =ROUND(Q14-R14,0) -> 9777 | T14: =ROUND(N($E14)*Paramètres!$C$13,0) -> 6407 | U14: =ROUND(MAX(0,N($E14)-(Q14-R14)-M14)*Paramètres!$C$12,0) -> 1920 | V14: =ROUND(N($E14)-M14-S14-U14,0) -> 190123
B15: 9 | C15: BILOGO Aline | D15: 46250 | E15: 0 | F15: =MIN(ROUNDDOWN(N($E15)*Paramètres!$C$16,0),Paramètres!$D$16) -> 0 | G15: =MIN(ROUNDDOWN(N($E15)*Paramètres!$C$17,0),Paramètres!$D$17) -> 0 | H15: =MIN(ROUNDDOWN(N($E15)*Paramètres!$C$18,0),Paramètres!$D$18) -> 0 | I15: =N($E15)-(F15+G15+H15) -> 0 | J15: 0 | K15: =IF(I15<Paramètres!$C$11,"Cadre inférieur","Cadre supérieur") -> Cadre inférieur | L15: =MIN(F15,MIN(N($E15)*Paramètres!$C$16,Paramètres!$D$16))+MIN(G15,MIN(N($E15)*Paramètres!$C$17,Paramètres!$D$17))+MIN(H15,MIN(N($E15)*Paramètres!$C$18,Paramètres!$D$18)) -> 0 | M15: =MIN(N($E15),Paramètres!$C$7)*Paramètres!$C$6 -> 0 | N15: =MIN(M15,I15*Paramètres!$C$8) -> 0 | O15: =I15*IF(K15="Cadre supérieur",Paramètres!$C$10,Paramètres!$C$9) -> 0 | P15: =MAX(0,ROUNDDOWN(N($E15)-L15-N15-O15,-2)) -> 0 | Q15: =SUMPRODUCT((P15>Paramètres!$B$21:$B$27)*(P15-Paramètres!$B$21:$B$27)*Paramètres!$E$21:$E$27) -> 0 | R15: =Q15*INDEX(Paramètres!$C$31:$C$38,MIN(MAX(INT(N(J15)),0),7)+1) -> 0 | S15: =ROUND(Q15-R15,0) -> 0 | T15: =ROUND(N($E15)*Paramètres!$C$13,0) -> 0 | U15: =ROUND(MAX(0,N($E15)-(Q15-R15)-M15)*Paramètres!$C$12,0) -> 0 | V15: =ROUND(N($E15)-M15-S15-U15,0) -> 0
B16: 10 | C16: BONKOUNGOU Judicael | D16: 45778 | E16: 213563 | F16: =MIN(ROUNDDOWN(N($E16)*Paramètres!$C$16,0),Paramètres!$D$16) -> 42712 | G16: =MIN(ROUNDDOWN(N($E16)*Paramètres!$C$17,0),Paramètres!$D$17) -> 10678 | H16: =MIN(ROUNDDOWN(N($E16)*Paramètres!$C$18,0),Paramètres!$D$18) -> 10678 | I16: =N($E16)-(F16+G16+H16) -> 149495 | J16: 0 | K16: =IF(I16<Paramètres!$C$11,"Cadre inférieur","Cadre supérieur") -> Cadre inférieur | L16: =MIN(F16,MIN(N($E16)*Paramètres!$C$16,Paramètres!$D$16))+MIN(G16,MIN(N($E16)*Paramètres!$C$17,Paramètres!$D$17))+MIN(H16,MIN(N($E16)*Paramètres!$C$18,Paramètres!$D$18)) -> 64068 | M16: =MIN(N($E16),Paramètres!$C$7)*Paramètres!$C$6 -> 11745.965 | N16: =MIN(M16,I16*Paramètres!$C$8) -> 11745.965 | O16: =I16*IF(K16="Cadre supérieur",Paramètres!$C$10,Paramètres!$C$9) -> 37373.75 | P16: =MAX(0,ROUNDDOWN(N($E16)-L16-N16-O16,-2)) -> 100300 | Q16: =SUMPRODUCT((P16>Paramètres!$B$21:$B$27)*(P16-Paramètres!$B$21:$B$27)*Paramètres!$E$21:$E$27) -> 9777.1 | R16: =Q16*INDEX(Paramètres!$C$31:$C$38,MIN(MAX(INT(N(J16)),0),7)+1) -> 0 | S16: =ROUND(Q16-R16,0) -> 9777 | T16: =ROUND(N($E16)*Paramètres!$C$13,0) -> 6407 | U16: =ROUND(MAX(0,N($E16)-(Q16-R16)-M16)*Paramètres!$C$12,0) -> 1920 | V16: =ROUND(N($E16)-M16-S16-U16,0) -> 190120
B17: 11 | C17: BONKOUNGOU Moussa | D17: 45778 | E17: 213563 | F17: =MIN(ROUNDDOWN(N($E17)*Paramètres!$C$16,0),Paramètres!$D$16) -> 42712 | G17: =MIN(ROUNDDOWN(N($E17)*Paramètres!$C$17,0),Paramètres!$D$17) -> 10678 | H17: =MIN(ROUNDDOWN(N($E17)*Paramètres!$C$18,0),Paramètres!$D$18) -> 10678 | I17: =N($E17)-(F17+G17+H17) -> 149495 | J17: 0 | K17: =IF(I17<Paramètres!$C$11,"Cadre inférieur","Cadre supérieur") -> Cadre inférieur | L17: =MIN(F17,MIN(N($E17)*Paramètres!$C$16,Paramètres!$D$16))+MIN(G17,MIN(N($E17)*Paramètres!$C$17,Paramètres!$D$17))+MIN(H17,MIN(N($E17)*Paramètres!$C$18,Paramètres!$D$18)) -> 64068 | M17: =MIN(N($E17),Paramètres!$C$7)*Paramètres!$C$6 -> 11745.965 | N17: =MIN(M17,I17*Paramètres!$C$8) -> 11745.965 | O17: =I17*IF(K17="Cadre supérieur",Paramètres!$C$10,Paramètres!$C$9) -> 37373.75 | P17: =MAX(0,ROUNDDOWN(N($E17)-L17-N17-O17,-2)) -> 100300 | Q17: =SUMPRODUCT((P17>Paramètres!$B$21:$B$27)*(P17-Paramètres!$B$21:$B$27)*Paramètres!$E$21:$E$27) -> 9777.1 | R17: =Q17*INDEX(Paramètres!$C$31:$C$38,MIN(MAX(INT(N(J17)),0),7)+1) -> 0 | S17: =ROUND(Q17-R17,0) -> 9777 | T17: =ROUND(N($E17)*Paramètres!$C$13,0) -> 6407 | U17: =ROUND(MAX(0,N($E17)-(Q17-R17)-M17)*Paramètres!$C$12,0) -> 1920 | V17: =ROUND(N($E17)-M17-S17-U17,0) -> 190120
B18: 12 | C18: BOUKARI Amidou | D18: 46183 | E18: 80000 | F18: =MIN(ROUNDDOWN(N($E18)*Paramètres!$C$16,0),Paramètres!$D$16) -> 16000 | G18: =MIN(ROUNDDOWN(N($E18)*Paramètres!$C$17,0),Paramètres!$D$17) -> 4000 | H18: =MIN(ROUNDDOWN(N($E18)*Paramètres!$C$18,0),Paramètres!$D$18) -> 4000 | I18: =N($E18)-(F18+G18+H18) -> 56000 | J18: 0 | K18: =IF(I18<Paramètres!$C$11,"Cadre inférieur","Cadre supérieur") -> Cadre inférieur | L18: =MIN(F18,MIN(N($E18)*Paramètres!$C$16,Paramètres!$D$16))+MIN(G18,MIN(N($E18)*Paramètres!$C$17,Paramètres!$D$17))+MIN(H18,MIN(N($E18)*Paramètres!$C$18,Paramètres!$D$18)) -> 24000 | M18: =MIN(N($E18),Paramètres!$C$7)*Paramètres!$C$6 -> 4400 | N18: =MIN(M18,I18*Paramètres!$C$8) -> 4400 | O18: =I18*IF(K18="Cadre supérieur",Paramètres!$C$10,Paramètres!$C$9) -> 14000 | P18: =MAX(0,ROUNDDOWN(N($E18)-L18-N18-O18,-2)) -> 37600 | Q18: =SUMPRODUCT((P18>Paramètres!$B$21:$B$27)*(P18-Paramètres!$B$21:$B$27)*Paramètres!$E$21:$E$27) -> 919.6 | R18: =Q18*INDEX(Paramètres!$C$31:$C$38,MIN(MAX(INT(N(J18)),0),7)+1) -> 0 | S18: =ROUND(Q18-R18,0) -> 920 | T18: =ROUND(N($E18)*Paramètres!$C$13,0) -> 2400 | U18: =ROUND(MAX(0,N($E18)-(Q18-R18)-M18)*Paramètres!$C$12,0) -> 747 | V18: =ROUND(N($E18)-M18-S18-U18,0) -> 73933
B19: 13 | C19: COULIBALY Ahmed | E19: 0 | F19: =MIN(ROUNDDOWN(N($E19)*Paramètres!$C$16,0),Paramètres!$D$16) -> 0 | G19: =MIN(ROUNDDOWN(N($E19)*Paramètres!$C$17,0),Paramètres!$D$17) -> 0 | H19: =MIN(ROUNDDOWN(N($E19)*Paramètres!$C$18,0),Paramètres!$D$18) -> 0 | I19: =N($E19)-(F19+G19+H19) -> 0 | J19: 0 | K19: =IF(I19<Paramètres!$C$11,"Cadre inférieur","Cadre supérieur") -> Cadre inférieur | L19: =MIN(F19,MIN(N($E19)*Paramètres!$C$16,Paramètres!$D$16))+MIN(G19,MIN(N($E19)*Paramètres!$C$17,Paramètres!$D$17))+MIN(H19,MIN(N($E19)*Paramètres!$C$18,Paramètres!$D$18)) -> 0 | M19: =MIN(N($E19),Paramètres!$C$7)*Paramètres!$C$6 -> 0 | N19: =MIN(M19,I19*Paramètres!$C$8) -> 0 | O19: =I19*IF(K19="Cadre supérieur",Paramètres!$C$10,Paramètres!$C$9) -> 0 | P19: =MAX(0,ROUNDDOWN(N($E19)-L19-N19-O19,-2)) -> 0 | Q19: =SUMPRODUCT((P19>Paramètres!$B$21:$B$27)*(P19-Paramètres!$B$21:$B$27)*Paramètres!$E$21:$E$27) -> 0 | R19: =Q19*INDEX(Paramètres!$C$31:$C$38,MIN(MAX(INT(N(J19)),0),7)+1) -> 0 | S19: =ROUND(Q19-R19,0) -> 0 | T19: =ROUND(N($E19)*Paramètres!$C$13,0) -> 0 | U19: =ROUND(MAX(0,N($E19)-(Q19-R19)-M19)*Paramètres!$C$12,0) -> 0 | V19: =ROUND(N($E19)-M19-S19-U19,0) -> 0
B20: 14 | C20: DIABATE Mohamed | D20: 45950 | E20: 177387 | F20: =MIN(ROUNDDOWN(N($E20)*Paramètres!$C$16,0),Paramètres!$D$16) -> 35477 | G20: =MIN(ROUNDDOWN(N($E20)*Paramètres!$C$17,0),Paramètres!$D$17) -> 8869 | H20: =MIN(ROUNDDOWN(N($E20)*Paramètres!$C$18,0),Paramètres!$D$18) -> 8869 | I20: =N($E20)-(F20+G20+H20) -> 124172 | J20: 0 | K20: =IF(I20<Paramètres!$C$11,"Cadre inférieur","Cadre supérieur") -> Cadre inférieur | L20: =MIN(F20,MIN(N($E20)*Paramètres!$C$16,Paramètres!$D$16))+MIN(G20,MIN(N($E20)*Paramètres!$C$17,Paramètres!$D$17))+MIN(H20,MIN(N($E20)*Paramètres!$C$18,Paramètres!$D$18)) -> 53215 | M20: =MIN(N($E20),Paramètres!$C$7)*Paramètres!$C$6 -> 9756.285 | N20: =MIN(M20,I20*Paramètres!$C$8) -> 9756.285 | O20: =I20*IF(K20="Cadre supérieur",Paramètres!$C$10,Paramètres!$C$9) -> 31043 | P20: =MAX(0,ROUNDDOWN(N($E20)-L20-N20-O20,-2)) -> 83300 | Q20: =SUMPRODUCT((P20>Paramètres!$B$21:$B$27)*(P20-Paramètres!$B$21:$B$27)*Paramètres!$E$21:$E$27) -> 7108.1 | R20: =Q20*INDEX(Paramètres!$C$31:$C$38,MIN(MAX(INT(N(J20)),0),7)+1) -> 0 | S20: =ROUND(Q20-R20,0) -> 7108 | T20: =ROUND(N($E20)*Paramètres!$C$13,0) -> 5322 | U20: =ROUND(MAX(0,N($E20)-(Q20-R20)-M20)*Paramètres!$C$12,0) -> 1605 | V20: =ROUND(N($E20)-M20-S20-U20,0) -> 158918
B21: 15 | C21: DIALLO Boureima | D21: 46183 | E21: 0 | F21: =MIN(ROUNDDOWN(N($E21)*Paramètres!$C$16,0),Paramètres!$D$16) -> 0 | G21: =MIN(ROUNDDOWN(N($E21)*Paramètres!$C$17,0),Paramètres!$D$17) -> 0 | H21: =MIN(ROUNDDOWN(N($E21)*Paramètres!$C$18,0),Paramètres!$D$18) -> 0 | I21: =N($E21)-(F21+G21+H21) -> 0 | J21: 0 | K21: =IF(I21<Paramètres!$C$11,"Cadre inférieur","Cadre supérieur") -> Cadre inférieur | L21: =MIN(F21,MIN(N($E21)*Paramètres!$C$16,Paramètres!$D$16))+MIN(G21,MIN(N($E21)*Paramètres!$C$17,Paramètres!$D$17))+MIN(H21,MIN(N($E21)*Paramètres!$C$18,Paramètres!$D$18)) -> 0 | M21: =MIN(N($E21),Paramètres!$C$7)*Paramètres!$C$6 -> 0 | N21: =MIN(M21,I21*Paramètres!$C$8) -> 0 | O21: =I21*IF(K21="Cadre supérieur",Paramètres!$C$10,Paramètres!$C$9) -> 0 | P21: =MAX(0,ROUNDDOWN(N($E21)-L21-N21-O21,-2)) -> 0 | Q21: =SUMPRODUCT((P21>Paramètres!$B$21:$B$27)*(P21-Paramètres!$B$21:$B$27)*Paramètres!$E$21:$E$27) -> 0 | R21: =Q21*INDEX(Paramètres!$C$31:$C$38,MIN(MAX(INT(N(J21)),0),7)+1) -> 0 | S21: =ROUND(Q21-R21,0) -> 0 | T21: =ROUND(N($E21)*Paramètres!$C$13,0) -> 0 | U21: =ROUND(MAX(0,N($E21)-(Q21-R21)-M21)*Paramètres!$C$12,0) -> 0 | V21: =ROUND(N($E21)-M21-S21-U21,0) -> 0
B22: 16 | C22: GANSONRE Alassane | D22: 46139 | E22: 135983 | F22: =MIN(ROUNDDOWN(N($E22)*Paramètres!$C$16,0),Paramètres!$D$16) -> 27196 | G22: =MIN(ROUNDDOWN(N($E22)*Paramètres!$C$17,0),Paramètres!$D$17) -> 6799 | H22: =MIN(ROUNDDOWN(N($E22)*Paramètres!$C$18,0),Paramètres!$D$18) -> 6799 | I22: =N($E22)-(F22+G22+H22) -> 95189 | J22: 0 | K22: =IF(I22<Paramètres!$C$11,"Cadre inférieur","Cadre supérieur") -> Cadre inférieur | L22: =MIN(F22,MIN(N($E22)*Paramètres!$C$16,Paramètres!$D$16))+MIN(G22,MIN(N($E22)*Paramètres!$C$17,Paramètres!$D$17))+MIN(H22,MIN(N($E22)*Paramètres!$C$18,Paramètres!$D$18)) -> 40794 | M22: =MIN(N($E22),Paramètres!$C$7)*Paramètres!$C$6 -> 7479.065 | N22: =MIN(M22,I22*Paramètres!$C$8) -> 7479.065 | O22: =I22*IF(K22="Cadre supérieur",Paramètres!$C$10,Paramètres!$C$9) -> 23797.25 | P22: =MAX(0,ROUNDDOWN(N($E22)-L22-N22-O22,-2)) -> 63900 | Q22: =SUMPRODUCT((P22>Paramètres!$B$21:$B$27)*(P22-Paramètres!$B$21:$B$27)*Paramètres!$E$21:$E$27) -> 4352.1 | R22: =Q22*INDEX(Paramètres!$C$31:$C$38,MIN(MAX(INT(N(J22)),0),7)+1) -> 0 | S22: =ROUND(Q22-R22,0) -> 4352 | T22: =ROUND(N($E22)*Paramètres!$C$13,0) -> 4079 | U22: =ROUND(MAX(0,N($E22)-(Q22-R22)-M22)*Paramètres!$C$12,0) -> 1242 | V22: =ROUND(N($E22)-M22-S22-U22,0) -> 122910
B23: 17 | C23: GOUBA Simon | D23: 45809 | E23: 135983 | F23: =MIN(ROUNDDOWN(N($E23)*Paramètres!$C$16,0),Paramètres!$D$16) -> 27196 | G23: =MIN(ROUNDDOWN(N($E23)*Paramètres!$C$17,0),Paramètres!$D$17) -> 6799 | H23: =MIN(ROUNDDOWN(N($E23)*Paramètres!$C$18,0),Paramètres!$D$18) -> 6799 | I23: =N($E23)-(F23+G23+H23) -> 95189 | J23: 0 | K23: =IF(I23<Paramètres!$C$11,"Cadre inférieur","Cadre supérieur") -> Cadre inférieur | L23: =MIN(F23,MIN(N($E23)*Paramètres!$C$16,Paramètres!$D$16))+MIN(G23,MIN(N($E23)*Paramètres!$C$17,Paramètres!$D$17))+MIN(H23,MIN(N($E23)*Paramètres!$C$18,Paramètres!$D$18)) -> 40794 | M23: =MIN(N($E23),Paramètres!$C$7)*Paramètres!$C$6 -> 7479.065 | N23: =MIN(M23,I23*Paramètres!$C$8) -> 7479.065 | O23: =I23*IF(K23="Cadre supérieur",Paramètres!$C$10,Paramètres!$C$9) -> 23797.25 | P23: =MAX(0,ROUNDDOWN(N($E23)-L23-N23-O23,-2)) -> 63900 | Q23: =SUMPRODUCT((P23>Paramètres!$B$21:$B$27)*(P23-Paramètres!$B$21:$B$27)*Paramètres!$E$21:$E$27) -> 4352.1 | R23: =Q23*INDEX(Paramètres!$C$31:$C$38,MIN(MAX(INT(N(J23)),0),7)+1) -> 0 | S23: =ROUND(Q23-R23,0) -> 4352 | T23: =ROUND(N($E23)*Paramètres!$C$13,0) -> 4079 | U23: =ROUND(MAX(0,N($E23)-(Q23-R23)-M23)*Paramètres!$C$12,0) -> 1242 | V23: =ROUND(N($E23)-M23-S23-U23,0) -> 122910
B24: 18 | C24: GOULLA Parbouré | D24: 46174 | E24: 0 | F24: =MIN(ROUNDDOWN(N($E24)*Paramètres!$C$16,0),Paramètres!$D$16) -> 0 | G24: =MIN(ROUNDDOWN(N($E24)*Paramètres!$C$17,0),Paramètres!$D$17) -> 0 | H24: =MIN(ROUNDDOWN(N($E24)*Paramètres!$C$18,0),Paramètres!$D$18) -> 0 | I24: =N($E24)-(F24+G24+H24) -> 0 | J24: 0 | K24: =IF(I24<Paramètres!$C$11,"Cadre inférieur","Cadre supérieur") -> Cadre inférieur | L24: =MIN(F24,MIN(N($E24)*Paramètres!$C$16,Paramètres!$D$16))+MIN(G24,MIN(N($E24)*Paramètres!$C$17,Paramètres!$D$17))+MIN(H24,MIN(N($E24)*Paramètres!$C$18,Paramètres!$D$18)) -> 0 | M24: =MIN(N($E24),Paramètres!$C$7)*Paramètres!$C$6 -> 0 | N24: =MIN(M24,I24*Paramètres!$C$8) -> 0 | O24: =I24*IF(K24="Cadre supérieur",Paramètres!$C$10,Paramètres!$C$9) -> 0 | P24: =MAX(0,ROUNDDOWN(N($E24)-L24-N24-O24,-2)) -> 0 | Q24: =SUMPRODUCT((P24>Paramètres!$B$21:$B$27)*(P24-Paramètres!$B$21:$B$27)*Paramètres!$E$21:$E$27) -> 0 | R24: =Q24*INDEX(Paramètres!$C$31:$C$38,MIN(MAX(INT(N(J24)),0),7)+1) -> 0 | S24: =ROUND(Q24-R24,0) -> 0 | T24: =ROUND(N($E24)*Paramètres!$C$13,0) -> 0 | U24: =ROUND(MAX(0,N($E24)-(Q24-R24)-M24)*Paramètres!$C$12,0) -> 0 | V24: =ROUND(N($E24)-M24-S24-U24,0) -> 0
B25: 19 | C25: GUIGUEMDE CALEB | D25: 45924 | E25: 0 | F25: =MIN(ROUNDDOWN(N($E25)*Paramètres!$C$16,0),Paramètres!$D$16) -> 0 | G25: =MIN(ROUNDDOWN(N($E25)*Paramètres!$C$17,0),Paramètres!$D$17) -> 0 | H25: =MIN(ROUNDDOWN(N($E25)*Paramètres!$C$18,0),Paramètres!$D$18) -> 0 | I25: =N($E25)-(F25+G25+H25) -> 0 | J25: 0 | K25: =IF(I25<Paramètres!$C$11,"Cadre inférieur","Cadre supérieur") -> Cadre inférieur | L25: =MIN(F25,MIN(N($E25)*Paramètres!$C$16,Paramètres!$D$16))+MIN(G25,MIN(N($E25)*Paramètres!$C$17,Paramètres!$D$17))+MIN(H25,MIN(N($E25)*Paramètres!$C$18,Paramètres!$D$18)) -> 0 | M25: =MIN(N($E25),Paramètres!$C$7)*Paramètres!$C$6 -> 0 | N25: =MIN(M25,I25*Paramètres!$C$8) -> 0 | O25: =I25*IF(K25="Cadre supérieur",Paramètres!$C$10,Paramètres!$C$9) -> 0 | P25: =MAX(0,ROUNDDOWN(N($E25)-L25-N25-O25,-2)) -> 0 | Q25: =SUMPRODUCT((P25>Paramètres!$B$21:$B$27)*(P25-Paramètres!$B$21:$B$27)*Paramètres!$E$21:$E$27) -> 0 | R25: =Q25*INDEX(Paramètres!$C$31:$C$38,MIN(MAX(INT(N(J25)),0),7)+1) -> 0 | S25: =ROUND(Q25-R25,0) -> 0 | T25: =ROUND(N($E25)*Paramètres!$C$13,0) -> 0 | U25: =ROUND(MAX(0,N($E25)-(Q25-R25)-M25)*Paramètres!$C$12,0) -> 0 | V25: =ROUND(N($E25)-M25-S25-U25,0) -> 0
B26: 20 | C26: ILBOUDO Alassane | D26: 46216 | E26: 135983 | F26: =MIN(ROUNDDOWN(N($E26)*Paramètres!$C$16,0),Paramètres!$D$16) -> 27196 | G26: =MIN(ROUNDDOWN(N($E26)*Paramètres!$C$17,0),Paramètres!$D$17) -> 6799 | H26: =MIN(ROUNDDOWN(N($E26)*Paramètres!$C$18,0),Paramètres!$D$18) -> 6799 | I26: =N($E26)-(F26+G26+H26) -> 95189 | J26: 0 | K26: =IF(I26<Paramètres!$C$11,"Cadre inférieur","Cadre supérieur") -> Cadre inférieur | L26: =MIN(F26,MIN(N($E26)*Paramètres!$C$16,Paramètres!$D$16))+MIN(G26,MIN(N($E26)*Paramètres!$C$17,Paramètres!$D$17))+MIN(H26,MIN(N($E26)*Paramètres!$C$18,Paramètres!$D$18)) -> 40794 | M26: =MIN(N($E26),Paramètres!$C$7)*Paramètres!$C$6 -> 7479.065 | N26: =MIN(M26,I26*Paramètres!$C$8) -> 7479.065 | O26: =I26*IF(K26="Cadre supérieur",Paramètres!$C$10,Paramètres!$C$9) -> 23797.25 | P26: =MAX(0,ROUNDDOWN(N($E26)-L26-N26-O26,-2)) -> 63900 | Q26: =SUMPRODUCT((P26>Paramètres!$B$21:$B$27)*(P26-Paramètres!$B$21:$B$27)*Paramètres!$E$21:$E$27) -> 4352.1 | R26: =Q26*INDEX(Paramètres!$C$31:$C$38,MIN(MAX(INT(N(J26)),0),7)+1) -> 0 | S26: =ROUND(Q26-R26,0) -> 4352 | T26: =ROUND(N($E26)*Paramètres!$C$13,0) -> 4079 | U26: =ROUND(MAX(0,N($E26)-(Q26-R26)-M26)*Paramètres!$C$12,0) -> 1242 | V26: =ROUND(N($E26)-M26-S26-U26,0) -> 122910
B27: 21 | C27: ILBOUDO Jean Marie | D27: 46000 | E27: 177387 | F27: =MIN(ROUNDDOWN(N($E27)*Paramètres!$C$16,0),Paramètres!$D$16) -> 35477 | G27: =MIN(ROUNDDOWN(N($E27)*Paramètres!$C$17,0),Paramètres!$D$17) -> 8869 | H27: =MIN(ROUNDDOWN(N($E27)*Paramètres!$C$18,0),Paramètres!$D$18) -> 8869 | I27: =N($E27)-(F27+G27+H27) -> 124172 | J27: 0 | K27: =IF(I27<Paramètres!$C$11,"Cadre inférieur","Cadre supérieur") -> Cadre inférieur | L27: =MIN(F27,MIN(N($E27)*Paramètres!$C$16,Paramètres!$D$16))+MIN(G27,MIN(N($E27)*Paramètres!$C$17,Paramètres!$D$17))+MIN(H27,MIN(N($E27)*Paramètres!$C$18,Paramètres!$D$18)) -> 53215 | M27: =MIN(N($E27),Paramètres!$C$7)*Paramètres!$C$6 -> 9756.285 | N27: =MIN(M27,I27*Paramètres!$C$8) -> 9756.285 | O27: =I27*IF(K27="Cadre supérieur",Paramètres!$C$10,Paramètres!$C$9) -> 31043 | P27: =MAX(0,ROUNDDOWN(N($E27)-L27-N27-O27,-2)) -> 83300 | Q27: =SUMPRODUCT((P27>Paramètres!$B$21:$B$27)*(P27-Paramètres!$B$21:$B$27)*Paramètres!$E$21:$E$27) -> 7108.1 | R27: =Q27*INDEX(Paramètres!$C$31:$C$38,MIN(MAX(INT(N(J27)),0),7)+1) -> 0 | S27: =ROUND(Q27-R27,0) -> 7108 | T27: =ROUND(N($E27)*Paramètres!$C$13,0) -> 5322 | U27: =ROUND(MAX(0,N($E27)-(Q27-R27)-M27)*Paramètres!$C$12,0) -> 1605 | V27: =ROUND(N($E27)-M27-S27-U27,0) -> 158918
B28: 22 | C28: ILBOUDO Zakaria | D28: 46283 | E28: 0 | F28: =MIN(ROUNDDOWN(N($E28)*Paramètres!$C$16,0),Paramètres!$D$16) -> 0 | G28: =MIN(ROUNDDOWN(N($E28)*Paramètres!$C$17,0),Paramètres!$D$17) -> 0 | H28: =MIN(ROUNDDOWN(N($E28)*Paramètres!$C$18,0),Paramètres!$D$18) -> 0 | I28: =N($E28)-(F28+G28+H28) -> 0 | J28: 0 | K28: =IF(I28<Paramètres!$C$11,"Cadre inférieur","Cadre supérieur") -> Cadre inférieur | L28: =MIN(F28,MIN(N($E28)*Paramètres!$C$16,Paramètres!$D$16))+MIN(G28,MIN(N($E28)*Paramètres!$C$17,Paramètres!$D$17))+MIN(H28,MIN(N($E28)*Paramètres!$C$18,Paramètres!$D$18)) -> 0 | M28: =MIN(N($E28),Paramètres!$C$7)*Paramètres!$C$6 -> 0 | N28: =MIN(M28,I28*Paramètres!$C$8) -> 0 | O28: =I28*IF(K28="Cadre supérieur",Paramètres!$C$10,Paramètres!$C$9) -> 0 | P28: =MAX(0,ROUNDDOWN(N($E28)-L28-N28-O28,-2)) -> 0 | Q28: =SUMPRODUCT((P28>Paramètres!$B$21:$B$27)*(P28-Paramètres!$B$21:$B$27)*Paramètres!$E$21:$E$27) -> 0 | R28: =Q28*INDEX(Paramètres!$C$31:$C$38,MIN(MAX(INT(N(J28)),0),7)+1) -> 0 | S28: =ROUND(Q28-R28,0) -> 0 | T28: =ROUND(N($E28)*Paramètres!$C$13,0) -> 0 | U28: =ROUND(MAX(0,N($E28)-(Q28-R28)-M28)*Paramètres!$C$12,0) -> 0 | V28: =ROUND(N($E28)-M28-S28-U28,0) -> 0
B29: 23 | C29: KABORE Abdoulaye | D29: 46204 | E29: 231913 | F29: =MIN(ROUNDDOWN(N($E29)*Paramètres!$C$16,0),Paramètres!$D$16) -> 46382 | G29: =MIN(ROUNDDOWN(N($E29)*Paramètres!$C$17,0),Paramètres!$D$17) -> 11595 | H29: =MIN(ROUNDDOWN(N($E29)*Paramètres!$C$18,0),Paramètres!$D$18) -> 11595 | I29: =N($E29)-(F29+G29+H29) -> 162341 | J29: 0 | K29: =IF(I29<Paramètres!$C$11,"Cadre inférieur","Cadre supérieur") -> Cadre supérieur | L29: =MIN(F29,MIN(N($E29)*Paramètres!$C$16,Paramètres!$D$16))+MIN(G29,MIN(N($E29)*Paramètres!$C$17,Paramètres!$D$17))+MIN(H29,MIN(N($E29)*Paramètres!$C$18,Paramètres!$D$18)) -> 69572 | M29: =MIN(N($E29),Paramètres!$C$7)*Paramètres!$C$6 -> 12755.215 | N29: =MIN(M29,I29*Paramètres!$C$8) -> 12755.215 | O29: =I29*IF(K29="Cadre supérieur",Paramètres!$C$10,Paramètres!$C$9) -> 32468.2 | P29: =MAX(0,ROUNDDOWN(N($E29)-L29-N29-O29,-2)) -> 117100 | Q29: =SUMPRODUCT((P29>Paramètres!$B$21:$B$27)*(P29-Paramètres!$B$21:$B$27)*Paramètres!$E$21:$E$27) -> 12414.7 | R29: =Q29*INDEX(Paramètres!$C$31:$C$38,MIN(MAX(INT(N(J29)),0),7)+1) -> 0 | S29: =ROUND(Q29-R29,0) -> 12415 | T29: =ROUND(N($E29)*Paramètres!$C$13,0) -> 6957 | U29: =ROUND(MAX(0,N($E29)-(Q29-R29)-M29)*Paramètres!$C$12,0) -> 2067 | V29: =ROUND(N($E29)-M29-S29-U29,0) -> 204676
B30: 24 | C30: KABORE Dramane | D30: 0107/2026 | E30: 0 | F30: =MIN(ROUNDDOWN(N($E30)*Paramètres!$C$16,0),Paramètres!$D$16) -> 0 | G30: =MIN(ROUNDDOWN(N($E30)*Paramètres!$C$17,0),Paramètres!$D$17) -> 0 | H30: =MIN(ROUNDDOWN(N($E30)*Paramètres!$C$18,0),Paramètres!$D$18) -> 0 | I30: =N($E30)-(F30+G30+H30) -> 0 | J30: 0 | K30: =IF(I30<Paramètres!$C$11,"Cadre inférieur","Cadre supérieur") -> Cadre inférieur | L30: =MIN(F30,MIN(N($E30)*Paramètres!$C$16,Paramètres!$D$16))+MIN(G30,MIN(N($E30)*Paramètres!$C$17,Paramètres!$D$17))+MIN(H30,MIN(N($E30)*Paramètres!$C$18,Paramètres!$D$18)) -> 0 | M30: =MIN(N($E30),Paramètres!$C$7)*Paramètres!$C$6 -> 0 | N30: =MIN(M30,I30*Paramètres!$C$8) -> 0 | O30: =I30*IF(K30="Cadre supérieur",Paramètres!$C$10,Paramètres!$C$9) -> 0 | P30: =MAX(0,ROUNDDOWN(N($E30)-L30-N30-O30,-2)) -> 0 | Q30: =SUMPRODUCT((P30>Paramètres!$B$21:$B$27)*(P30-Paramètres!$B$21:$B$27)*Paramètres!$E$21:$E$27) -> 0 | R30: =Q30*INDEX(Paramètres!$C$31:$C$38,MIN(MAX(INT(N(J30)),0),7)+1) -> 0 | S30: =ROUND(Q30-R30,0) -> 0 | T30: =ROUND(N($E30)*Paramètres!$C$13,0) -> 0 | U30: =ROUND(MAX(0,N($E30)-(Q30-R30)-M30)*Paramètres!$C$12,0) -> 0 | V30: =ROUND(N($E30)-M30-S30-U30,0) -> 0
B31: 25 | C31: KABORE Lassane | D31: 45778 | E31: 165340 | F31: =MIN(ROUNDDOWN(N($E31)*Paramètres!$C$16,0),Paramètres!$D$16) -> 33068 | G31: =MIN(ROUNDDOWN(N($E31)*Paramètres!$C$17,0),Paramètres!$D$17) -> 8267 | H31: =MIN(ROUNDDOWN(N($E31)*Paramètres!$C$18,0),Paramètres!$D$18) -> 8267 | I31: =N($E31)-(F31+G31+H31) -> 115738 | J31: 0 | K31: =IF(I31<Paramètres!$C$11,"Cadre inférieur","Cadre supérieur") -> Cadre inférieur | L31: =MIN(F31,MIN(N($E31)*Paramètres!$C$16,Paramètres!$D$16))+MIN(G31,MIN(N($E31)*Paramètres!$C$17,Paramètres!$D$17))+MIN(H31,MIN(N($E31)*Paramètres!$C$18,Paramètres!$D$18)) -> 49602 | M31: =MIN(N($E31),Paramètres!$C$7)*Paramètres!$C$6 -> 9093.7 | N31: =MIN(M31,I31*Paramètres!$C$8) -> 9093.7 | O31: =I31*IF(K31="Cadre supérieur",Paramètres!$C$10,Paramètres!$C$9) -> 28934.5 | P31: =MAX(0,ROUNDDOWN(N($E31)-L31-N31-O31,-2)) -> 77700 | Q31: =SUMPRODUCT((P31>Paramètres!$B$21:$B$27)*(P31-Paramètres!$B$21:$B$27)*Paramètres!$E$21:$E$27) -> 6270.3 | R31: =Q31*INDEX(Paramètres!$C$31:$C$38,MIN(MAX(INT(N(J31)),0),7)+1) -> 0 | S31: =ROUND(Q31-R31,0) -> 6270 | T31: =ROUND(N($E31)*Paramètres!$C$13,0) -> 4960 | U31: =ROUND(MAX(0,N($E31)-(Q31-R31)-M31)*Paramètres!$C$12,0) -> 1500 | V31: =ROUND(N($E31)-M31-S31-U31,0) -> 148476
B32: 26 | C32: KABORE Sid Mohamed | D32: 46183 | E32: 80000 | F32: =MIN(ROUNDDOWN(N($E32)*Paramètres!$C$16,0),Paramètres!$D$16) -> 16000 | G32: =MIN(ROUNDDOWN(N($E32)*Paramètres!$C$17,0),Paramètres!$D$17) -> 4000 | H32: =MIN(ROUNDDOWN(N($E32)*Paramètres!$C$18,0),Paramètres!$D$18) -> 4000 | I32: =N($E32)-(F32+G32+H32) -> 56000 | J32: 0 | K32: =IF(I32<Paramètres!$C$11,"Cadre inférieur","Cadre supérieur") -> Cadre inférieur | L32: =MIN(F32,MIN(N($E32)*Paramètres!$C$16,Paramètres!$D$16))+MIN(G32,MIN(N($E32)*Paramètres!$C$17,Paramètres!$D$17))+MIN(H32,MIN(N($E32)*Paramètres!$C$18,Paramètres!$D$18)) -> 24000 | M32: =MIN(N($E32),Paramètres!$C$7)*Paramètres!$C$6 -> 4400 | N32: =MIN(M32,I32*Paramètres!$C$8) -> 4400 | O32: =I32*IF(K32="Cadre supérieur",Paramètres!$C$10,Paramètres!$C$9) -> 14000 | P32: =MAX(0,ROUNDDOWN(N($E32)-L32-N32-O32,-2)) -> 37600 | Q32: =SUMPRODUCT((P32>Paramètres!$B$21:$B$27)*(P32-Paramètres!$B$21:$B$27)*Paramètres!$E$21:$E$27) -> 919.6 | R32: =Q32*INDEX(Paramètres!$C$31:$C$38,MIN(MAX(INT(N(J32)),0),7)+1) -> 0 | S32: =ROUND(Q32-R32,0) -> 920 | T32: =ROUND(N($E32)*Paramètres!$C$13,0) -> 2400 | U32: =ROUND(MAX(0,N($E32)-(Q32-R32)-M32)*Paramètres!$C$12,0) -> 747 | V32: =ROUND(N($E32)-M32-S32-U32,0) -> 73933
B33: 27 | C33: KABRE Ali | E33: 346515 | F33: =MIN(ROUNDDOWN(N($E33)*Paramètres!$C$16,0),Paramètres!$D$16) -> 69303 | G33: =MIN(ROUNDDOWN(N($E33)*Paramètres!$C$17,0),Paramètres!$D$17) -> 17325 | H33: =MIN(ROUNDDOWN(N($E33)*Paramètres!$C$18,0),Paramètres!$D$18) -> 17325 | I33: =N($E33)-(F33+G33+H33) -> 242562 | J33: 0 | K33: =IF(I33<Paramètres!$C$11,"Cadre inférieur","Cadre supérieur") -> Cadre supérieur | L33: =MIN(F33,MIN(N($E33)*Paramètres!$C$16,Paramètres!$D$16))+MIN(G33,MIN(N($E33)*Paramètres!$C$17,Paramètres!$D$17))+MIN(H33,MIN(N($E33)*Paramètres!$C$18,Paramètres!$D$18)) -> 103953 | M33: =MIN(N($E33),Paramètres!$C$7)*Paramètres!$C$6 -> 19058.325 | N33: =MIN(M33,I33*Paramètres!$C$8) -> 19058.325 | O33: =I33*IF(K33="Cadre supérieur",Paramètres!$C$10,Paramètres!$C$9) -> 48512.4 | P33: =MAX(0,ROUNDDOWN(N($E33)-L33-N33-O33,-2)) -> 174900 | Q33: =SUMPRODUCT((P33>Paramètres!$B$21:$B$27)*(P33-Paramètres!$B$21:$B$27)*Paramètres!$E$21:$E$27) -> 23133.3 | R33: =Q33*INDEX(Paramètres!$C$31:$C$38,MIN(MAX(INT(N(J33)),0),7)+1) -> 0 | S33: =ROUND(Q33-R33,0) -> 23133 | T33: =ROUND(N($E33)*Paramètres!$C$13,0) -> 10395 | U33: =ROUND(MAX(0,N($E33)-(Q33-R33)-M33)*Paramètres!$C$12,0) -> 3043 | V33: =ROUND(N($E33)-M33-S33-U33,0) -> 301281
B34: 28 | C34: KABRE Daouda | D34: 45965 | E34: 0 | F34: =MIN(ROUNDDOWN(N($E34)*Paramètres!$C$16,0),Paramètres!$D$16) -> 0 | G34: =MIN(ROUNDDOWN(N($E34)*Paramètres!$C$17,0),Paramètres!$D$17) -> 0 | H34: =MIN(ROUNDDOWN(N($E34)*Paramètres!$C$18,0),Paramètres!$D$18) -> 0 | I34: =N($E34)-(F34+G34+H34) -> 0 | J34: 0 | K34: =IF(I34<Paramètres!$C$11,"Cadre inférieur","Cadre supérieur") -> Cadre inférieur | L34: =MIN(F34,MIN(N($E34)*Paramètres!$C$16,Paramètres!$D$16))+MIN(G34,MIN(N($E34)*Paramètres!$C$17,Paramètres!$D$17))+MIN(H34,MIN(N($E34)*Paramètres!$C$18,Paramètres!$D$18)) -> 0 | M34: =MIN(N($E34),Paramètres!$C$7)*Paramètres!$C$6 -> 0 | N34: =MIN(M34,I34*Paramètres!$C$8) -> 0 | O34: =I34*IF(K34="Cadre supérieur",Paramètres!$C$10,Paramètres!$C$9) -> 0 | P34: =MAX(0,ROUNDDOWN(N($E34)-L34-N34-O34,-2)) -> 0 | Q34: =SUMPRODUCT((P34>Paramètres!$B$21:$B$27)*(P34-Paramètres!$B$21:$B$27)*Paramètres!$E$21:$E$27) -> 0 | R34: =Q34*INDEX(Paramètres!$C$31:$C$38,MIN(MAX(INT(N(J34)),0),7)+1) -> 0 | S34: =ROUND(Q34-R34,0) -> 0 | T34: =ROUND(N($E34)*Paramètres!$C$13,0) -> 0 | U34: =ROUND(MAX(0,N($E34)-(Q34-R34)-M34)*Paramètres!$C$12,0) -> 0 | V34: =ROUND(N($E34)-M34-S34-U34,0) -> 0
B35: 29 | C35: KABRE Esther | D35: 46092 | E35: 165340 | F35: =MIN(ROUNDDOWN(N($E35)*Paramètres!$C$16,0),Paramètres!$D$16) -> 33068 | G35: =MIN(ROUNDDOWN(N($E35)*Paramètres!$C$17,0),Paramètres!$D$17) -> 8267 | H35: =MIN(ROUNDDOWN(N($E35)*Paramètres!$C$18,0),Paramètres!$D$18) -> 8267 | I35: =N($E35)-(F35+G35+H35) -> 115738 | J35: 0 | K35: =IF(I35<Paramètres!$C$11,"Cadre inférieur","Cadre supérieur") -> Cadre inférieur | L35: =MIN(F35,MIN(N($E35)*Paramètres!$C$16,Paramètres!$D$16))+MIN(G35,MIN(N($E35)*Paramètres!$C$17,Paramètres!$D$17))+MIN(H35,MIN(N($E35)*Paramètres!$C$18,Paramètres!$D$18)) -> 49602 | M35: =MIN(N($E35),Paramètres!$C$7)*Paramètres!$C$6 -> 9093.7 | N35: =MIN(M35,I35*Paramètres!$C$8) -> 9093.7 | O35: =I35*IF(K35="Cadre supérieur",Paramètres!$C$10,Paramètres!$C$9) -> 28934.5 | P35: =MAX(0,ROUNDDOWN(N($E35)-L35-N35-O35,-2)) -> 77700 | Q35: =SUMPRODUCT((P35>Paramètres!$B$21:$B$27)*(P35-Paramètres!$B$21:$B$27)*Paramètres!$E$21:$E$27) -> 6270.3 | R35: =Q35*INDEX(Paramètres!$C$31:$C$38,MIN(MAX(INT(N(J35)),0),7)+1) -> 0 | S35: =ROUND(Q35-R35,0) -> 6270 | T35: =ROUND(N($E35)*Paramètres!$C$13,0) -> 4960 | U35: =ROUND(MAX(0,N($E35)-(Q35-R35)-M35)*Paramètres!$C$12,0) -> 1500 | V35: =ROUND(N($E35)-M35-S35-U35,0) -> 148476
B36: 30 | C36: KARAMA Youmati | E36: 195448 | F36: =MIN(ROUNDDOWN(N($E36)*Paramètres!$C$16,0),Paramètres!$D$16) -> 39089 | G36: =MIN(ROUNDDOWN(N($E36)*Paramètres!$C$17,0),Paramètres!$D$17) -> 9772 | H36: =MIN(ROUNDDOWN(N($E36)*Paramètres!$C$18,0),Paramètres!$D$18) -> 9772 | I36: =N($E36)-(F36+G36+H36) -> 136815 | J36: 0 | K36: =IF(I36<Paramètres!$C$11,"Cadre inférieur","Cadre supérieur") -> Cadre inférieur | L36: =MIN(F36,MIN(N($E36)*Paramètres!$C$16,Paramètres!$D$16))+MIN(G36,MIN(N($E36)*Paramètres!$C$17,Paramètres!$D$17))+MIN(H36,MIN(N($E36)*Paramètres!$C$18,Paramètres!$D$18)) -> 58633 | M36: =MIN(N($E36),Paramètres!$C$7)*Paramètres!$C$6 -> 10749.64 | N36: =MIN(M36,I36*Paramètres!$C$8) -> 10749.64 | O36: =I36*IF(K36="Cadre supérieur",Paramètres!$C$10,Paramètres!$C$9) -> 34203.75 | P36: =MAX(0,ROUNDDOWN(N($E36)-L36-N36-O36,-2)) -> 91800 | Q36: =SUMPRODUCT((P36>Paramètres!$B$21:$B$27)*(P36-Paramètres!$B$21:$B$27)*Paramètres!$E$21:$E$27) -> 8442.6 | R36: =Q36*INDEX(Paramètres!$C$31:$C$38,MIN(MAX(INT(N(J36)),0),7)+1) -> 0 | S36: =ROUND(Q36-R36,0) -> 8443 | T36: =ROUND(N($E36)*Paramètres!$C$13,0) -> 5863 | U36: =ROUND(MAX(0,N($E36)-(Q36-R36)-M36)*Paramètres!$C$12,0) -> 1763 | V36: =ROUND(N($E36)-M36-S36-U36,0) -> 174492
B37: 31 | C37: KAZIENGA PascaL | D37: 46275 | E37: 0 | F37: =MIN(ROUNDDOWN(N($E37)*Paramètres!$C$16,0),Paramètres!$D$16) -> 0 | G37: =MIN(ROUNDDOWN(N($E37)*Paramètres!$C$17,0),Paramètres!$D$17) -> 0 | H37: =MIN(ROUNDDOWN(N($E37)*Paramètres!$C$18,0),Paramètres!$D$18) -> 0 | I37: =N($E37)-(F37+G37+H37) -> 0 | J37: 0 | K37: =IF(I37<Paramètres!$C$11,"Cadre inférieur","Cadre supérieur") -> Cadre inférieur | L37: =MIN(F37,MIN(N($E37)*Paramètres!$C$16,Paramètres!$D$16))+MIN(G37,MIN(N($E37)*Paramètres!$C$17,Paramètres!$D$17))+MIN(H37,MIN(N($E37)*Paramètres!$C$18,Paramètres!$D$18)) -> 0 | M37: =MIN(N($E37),Paramètres!$C$7)*Paramètres!$C$6 -> 0 | N37: =MIN(M37,I37*Paramètres!$C$8) -> 0 | O37: =I37*IF(K37="Cadre supérieur",Paramètres!$C$10,Paramètres!$C$9) -> 0 | P37: =MAX(0,ROUNDDOWN(N($E37)-L37-N37-O37,-2)) -> 0 | Q37: =SUMPRODUCT((P37>Paramètres!$B$21:$B$27)*(P37-Paramètres!$B$21:$B$27)*Paramètres!$E$21:$E$27) -> 0 | R37: =Q37*INDEX(Paramètres!$C$31:$C$38,MIN(MAX(INT(N(J37)),0),7)+1) -> 0 | S37: =ROUND(Q37-R37,0) -> 0 | T37: =ROUND(N($E37)*Paramètres!$C$13,0) -> 0 | U37: =ROUND(MAX(0,N($E37)-(Q37-R37)-M37)*Paramètres!$C$12,0) -> 0 | V37: =ROUND(N($E37)-M37-S37-U37,0) -> 0
B38: 32 | C38: KOANDA Souleymane | D38: 46216 | E38: 135983 | F38: =MIN(ROUNDDOWN(N($E38)*Paramètres!$C$16,0),Paramètres!$D$16) -> 27196 | G38: =MIN(ROUNDDOWN(N($E38)*Paramètres!$C$17,0),Paramètres!$D$17) -> 6799 | H38: =MIN(ROUNDDOWN(N($E38)*Paramètres!$C$18,0),Paramètres!$D$18) -> 6799 | I38: =N($E38)-(F38+G38+H38) -> 95189 | J38: 0 | K38: =IF(I38<Paramètres!$C$11,"Cadre inférieur","Cadre supérieur") -> Cadre inférieur | L38: =MIN(F38,MIN(N($E38)*Paramètres!$C$16,Paramètres!$D$16))+MIN(G38,MIN(N($E38)*Paramètres!$C$17,Paramètres!$D$17))+MIN(H38,MIN(N($E38)*Paramètres!$C$18,Paramètres!$D$18)) -> 40794 | M38: =MIN(N($E38),Paramètres!$C$7)*Paramètres!$C$6 -> 7479.065 | N38: =MIN(M38,I38*Paramètres!$C$8) -> 7479.065 | O38: =I38*IF(K38="Cadre supérieur",Paramètres!$C$10,Paramètres!$C$9) -> 23797.25 | P38: =MAX(0,ROUNDDOWN(N($E38)-L38-N38-O38,-2)) -> 63900 | Q38: =SUMPRODUCT((P38>Paramètres!$B$21:$B$27)*(P38-Paramètres!$B$21:$B$27)*Paramètres!$E$21:$E$27) -> 4352.1 | R38: =Q38*INDEX(Paramètres!$C$31:$C$38,MIN(MAX(INT(N(J38)),0),7)+1) -> 0 | S38: =ROUND(Q38-R38,0) -> 4352 | T38: =ROUND(N($E38)*Paramètres!$C$13,0) -> 4079 | U38: =ROUND(MAX(0,N($E38)-(Q38-R38)-M38)*Paramètres!$C$12,0) -> 1242 | V38: =ROUND(N($E38)-M38-S38-U38,0) -> 122910
B39: 33 | C39: KOMPAORE Anicet | D39: 45778 | E39: 346515 | F39: =MIN(ROUNDDOWN(N($E39)*Paramètres!$C$16,0),Paramètres!$D$16) -> 69303 | G39: =MIN(ROUNDDOWN(N($E39)*Paramètres!$C$17,0),Paramètres!$D$17) -> 17325 | H39: =MIN(ROUNDDOWN(N($E39)*Paramètres!$C$18,0),Paramètres!$D$18) -> 17325 | I39: =N($E39)-(F39+G39+H39) -> 242562 | J39: 0 | K39: =IF(I39<Paramètres!$C$11,"Cadre inférieur","Cadre supérieur") -> Cadre supérieur | L39: =MIN(F39,MIN(N($E39)*Paramètres!$C$16,Paramètres!$D$16))+MIN(G39,MIN(N($E39)*Paramètres!$C$17,Paramètres!$D$17))+MIN(H39,MIN(N($E39)*Paramètres!$C$18,Paramètres!$D$18)) -> 103953 | M39: =MIN(N($E39),Paramètres!$C$7)*Paramètres!$C$6 -> 19058.325 | N39: =MIN(M39,I39*Paramètres!$C$8) -> 19058.325 | O39: =I39*IF(K39="Cadre supérieur",Paramètres!$C$10,Paramètres!$C$9) -> 48512.4 | P39: =MAX(0,ROUNDDOWN(N($E39)-L39-N39-O39,-2)) -> 174900 | Q39: =SUMPRODUCT((P39>Paramètres!$B$21:$B$27)*(P39-Paramètres!$B$21:$B$27)*Paramètres!$E$21:$E$27) -> 23133.3 | R39: =Q39*INDEX(Paramètres!$C$31:$C$38,MIN(MAX(INT(N(J39)),0),7)+1) -> 0 | S39: =ROUND(Q39-R39,0) -> 23133 | T39: =ROUND(N($E39)*Paramètres!$C$13,0) -> 10395 | U39: =ROUND(MAX(0,N($E39)-(Q39-R39)-M39)*Paramètres!$C$12,0) -> 3043 | V39: =ROUND(N($E39)-M39-S39-U39,0) -> 301281
B40: 34 | C40: KONE Tidiane | D40: 45962 | E40: 213563 | F40: =MIN(ROUNDDOWN(N($E40)*Paramètres!$C$16,0),Paramètres!$D$16) -> 42712 | G40: =MIN(ROUNDDOWN(N($E40)*Paramètres!$C$17,0),Paramètres!$D$17) -> 10678 | H40: =MIN(ROUNDDOWN(N($E40)*Paramètres!$C$18,0),Paramètres!$D$18) -> 10678 | I40: =N($E40)-(F40+G40+H40) -> 149495 | J40: 0 | K40: =IF(I40<Paramètres!$C$11,"Cadre inférieur","Cadre supérieur") -> Cadre inférieur | L40: =MIN(F40,MIN(N($E40)*Paramètres!$C$16,Paramètres!$D$16))+MIN(G40,MIN(N($E40)*Paramètres!$C$17,Paramètres!$D$17))+MIN(H40,MIN(N($E40)*Paramètres!$C$18,Paramètres!$D$18)) -> 64068 | M40: =MIN(N($E40),Paramètres!$C$7)*Paramètres!$C$6 -> 11745.965 | N40: =MIN(M40,I40*Paramètres!$C$8) -> 11745.965 | O40: =I40*IF(K40="Cadre supérieur",Paramètres!$C$10,Paramètres!$C$9) -> 37373.75 | P40: =MAX(0,ROUNDDOWN(N($E40)-L40-N40-O40,-2)) -> 100300 | Q40: =SUMPRODUCT((P40>Paramètres!$B$21:$B$27)*(P40-Paramètres!$B$21:$B$27)*Paramètres!$E$21:$E$27) -> 9777.1 | R40: =Q40*INDEX(Paramètres!$C$31:$C$38,MIN(MAX(INT(N(J40)),0),7)+1) -> 0 | S40: =ROUND(Q40-R40,0) -> 9777 | T40: =ROUND(N($E40)*Paramètres!$C$13,0) -> 6407 | U40: =ROUND(MAX(0,N($E40)-(Q40-R40)-M40)*Paramètres!$C$12,0) -> 1920 | V40: =ROUND(N($E40)-M40-S40-U40,0) -> 190120
B41: 35 | C41: KONSIMBO A. Aziz | D41: 46252 | E41: 0 | F41: =MIN(ROUNDDOWN(N($E41)*Paramètres!$C$16,0),Paramètres!$D$16) -> 0 | G41: =MIN(ROUNDDOWN(N($E41)*Paramètres!$C$17,0),Paramètres!$D$17) -> 0 | H41: =MIN(ROUNDDOWN(N($E41)*Paramètres!$C$18,0),Paramètres!$D$18) -> 0 | I41: =N($E41)-(F41+G41+H41) -> 0 | J41: 0 | K41: =IF(I41<Paramètres!$C$11,"Cadre inférieur","Cadre supérieur") -> Cadre inférieur | L41: =MIN(F41,MIN(N($E41)*Paramètres!$C$16,Paramètres!$D$16))+MIN(G41,MIN(N($E41)*Paramètres!$C$17,Paramètres!$D$17))+MIN(H41,MIN(N($E41)*Paramètres!$C$18,Paramètres!$D$18)) -> 0 | M41: =MIN(N($E41),Paramètres!$C$7)*Paramètres!$C$6 -> 0 | N41: =MIN(M41,I41*Paramètres!$C$8) -> 0 | O41: =I41*IF(K41="Cadre supérieur",Paramètres!$C$10,Paramètres!$C$9) -> 0 | P41: =MAX(0,ROUNDDOWN(N($E41)-L41-N41-O41,-2)) -> 0 | Q41: =SUMPRODUCT((P41>Paramètres!$B$21:$B$27)*(P41-Paramètres!$B$21:$B$27)*Paramètres!$E$21:$E$27) -> 0 | R41: =Q41*INDEX(Paramètres!$C$31:$C$38,MIN(MAX(INT(N(J41)),0),7)+1) -> 0 | S41: =ROUND(Q41-R41,0) -> 0 | T41: =ROUND(N($E41)*Paramètres!$C$13,0) -> 0 | U41: =ROUND(MAX(0,N($E41)-(Q41-R41)-M41)*Paramètres!$C$12,0) -> 0 | V41: =ROUND(N($E41)-M41-S41-U41,0) -> 0
B42: 36 | C42: MAIGA Harisso | D42: 46023 | E42: 213563 | F42: =MIN(ROUNDDOWN(N($E42)*Paramètres!$C$16,0),Paramètres!$D$16) -> 42712 | G42: =MIN(ROUNDDOWN(N($E42)*Paramètres!$C$17,0),Paramètres!$D$17) -> 10678 | H42: =MIN(ROUNDDOWN(N($E42)*Paramètres!$C$18,0),Paramètres!$D$18) -> 10678 | I42: =N($E42)-(F42+G42+H42) -> 149495 | J42: 0 | K42: =IF(I42<Paramètres!$C$11,"Cadre inférieur","Cadre supérieur") -> Cadre inférieur | L42: =MIN(F42,MIN(N($E42)*Paramètres!$C$16,Paramètres!$D$16))+MIN(G42,MIN(N($E42)*Paramètres!$C$17,Paramètres!$D$17))+MIN(H42,MIN(N($E42)*Paramètres!$C$18,Paramètres!$D$18)) -> 64068 | M42: =MIN(N($E42),Paramètres!$C$7)*Paramètres!$C$6 -> 11745.965 | N42: =MIN(M42,I42*Paramètres!$C$8) -> 11745.965 | O42: =I42*IF(K42="Cadre supérieur",Paramètres!$C$10,Paramètres!$C$9) -> 37373.75 | P42: =MAX(0,ROUNDDOWN(N($E42)-L42-N42-O42,-2)) -> 100300 | Q42: =SUMPRODUCT((P42>Paramètres!$B$21:$B$27)*(P42-Paramètres!$B$21:$B$27)*Paramètres!$E$21:$E$27) -> 9777.1 | R42: =Q42*INDEX(Paramètres!$C$31:$C$38,MIN(MAX(INT(N(J42)),0),7)+1) -> 0 | S42: =ROUND(Q42-R42,0) -> 9777 | T42: =ROUND(N($E42)*Paramètres!$C$13,0) -> 6407 | U42: =ROUND(MAX(0,N($E42)-(Q42-R42)-M42)*Paramètres!$C$12,0) -> 1920 | V42: =ROUND(N($E42)-M42-S42-U42,0) -> 190120
B43: 37 | C43: NANEMA Roger | D43: 46220 | E43: 0 | F43: =MIN(ROUNDDOWN(N($E43)*Paramètres!$C$16,0),Paramètres!$D$16) -> 0 | G43: =MIN(ROUNDDOWN(N($E43)*Paramètres!$C$17,0),Paramètres!$D$17) -> 0 | H43: =MIN(ROUNDDOWN(N($E43)*Paramètres!$C$18,0),Paramètres!$D$18) -> 0 | I43: =N($E43)-(F43+G43+H43) -> 0 | J43: 0 | K43: =IF(I43<Paramètres!$C$11,"Cadre inférieur","Cadre supérieur") -> Cadre inférieur | L43: =MIN(F43,MIN(N($E43)*Paramètres!$C$16,Paramètres!$D$16))+MIN(G43,MIN(N($E43)*Paramètres!$C$17,Paramètres!$D$17))+MIN(H43,MIN(N($E43)*Paramètres!$C$18,Paramètres!$D$18)) -> 0 | M43: =MIN(N($E43),Paramètres!$C$7)*Paramètres!$C$6 -> 0 | N43: =MIN(M43,I43*Paramètres!$C$8) -> 0 | O43: =I43*IF(K43="Cadre supérieur",Paramètres!$C$10,Paramètres!$C$9) -> 0 | P43: =MAX(0,ROUNDDOWN(N($E43)-L43-N43-O43,-2)) -> 0 | Q43: =SUMPRODUCT((P43>Paramètres!$B$21:$B$27)*(P43-Paramètres!$B$21:$B$27)*Paramètres!$E$21:$E$27) -> 0 | R43: =Q43*INDEX(Paramètres!$C$31:$C$38,MIN(MAX(INT(N(J43)),0),7)+1) -> 0 | S43: =ROUND(Q43-R43,0) -> 0 | T43: =ROUND(N($E43)*Paramètres!$C$13,0) -> 0 | U43: =ROUND(MAX(0,N($E43)-(Q43-R43)-M43)*Paramètres!$C$12,0) -> 0 | V43: =ROUND(N($E43)-M43-S43-U43,0) -> 0
...

Sheet Août
B4: ETAT DES SALAIRES KS SARL
B5: Période: | D5: AOUT 2026 | J5: Hypothèses | L5: Calcul IUTS | T5: TPA, Rosalaire et net
B6: N° | C6: Nom&Prénom | D6: DATE D'ENTREE | E6: BASE | F6: Ind. Logement | G6: Ind. Transport | H6: Ind. Fonction | I6: Brut | J6: Nb charges | K6: Catégorie | L6: Montant exonéré | M6: CNSS salarié 5,5 % | N6: Déduction retraite | O6: Abattement forfaitaire | P6: Base imposable (arr. 100) | Q6: IUTS brut | R6: Réduction charges | S6: IUTS NET | T6: TPA 3 % (patronale) | U6: Rosalaire 1 % | V6: SALAIRE NET À PAYER
B7: 1 | C7: BAGAGNAN Salima | D7: 46242 | E7: =+I7-(F7+G7+H7) -> 56000 | F7: 16000 | G7: 4000 | H7: 4000 | I7: 80000 | J7: 0 | K7: =IF(E7<Paramètres!$C$11,"Cadre inférieur","Cadre supérieur") -> Cadre inférieur | L7: =MIN(F7,MIN(N($I7)*Paramètres!$C$16,Paramètres!$D$16))+MIN(G7,MIN(N($I7)*Paramètres!$C$17,Paramètres!$D$17))+MIN(H7,MIN(N($I7)*Paramètres!$C$18,Paramètres!$D$18)) -> 24000 | M7: =MIN(N($I7),Paramètres!$C$7)*Paramètres!$C$6 -> 4400 | N7: =MIN(M7,E7*Paramètres!$C$8) -> 4400 | O7: =E7*IF(K7="Cadre supérieur",Paramètres!$C$10,Paramètres!$C$9) -> 14000 | P7: =MAX(0,ROUNDDOWN(N($I7)-L7-N7-O7,-2)) -> 37600 | Q7: =SUMPRODUCT((P7>Paramètres!$B$21:$B$27)*(P7-Paramètres!$B$21:$B$27)*Paramètres!$E$21:$E$27) -> 919.6 | R7: =Q7*INDEX(Paramètres!$C$31:$C$38,MIN(MAX(INT(N(J7)),0),7)+1) -> 0 | S7: =ROUND(Q7-R7,0) -> 920 | T7: =ROUND(N($I7)*Paramètres!$C$13,0) -> 2400 | U7: =ROUND(MAX(0,N($I7)-(Q7-R7)-M7)*Paramètres!$C$12,0) -> 747 | V7: =ROUND(N($I7)-M7-S7-U7,0) -> 73933
B8: 2 | C8: BANHORO Adama | D8: 46196 | E8: =+I8-(F8+G8+H8) -> 95189 | F8: =MIN(ROUNDDOWN(N($I8)*Paramètres!$C$16,0),Paramètres!$D$16) -> 27196 | G8: =MIN(ROUNDDOWN(N($I8)*Paramètres!$C$17,0),Paramètres!$D$17) -> 6799 | H8: =MIN(ROUNDDOWN(N($I8)*Paramètres!$C$18,0),Paramètres!$D$18) -> 6799 | I8: 135983 | J8: 0 | K8: =IF(E8<Paramètres!$C$11,"Cadre inférieur","Cadre supérieur") -> Cadre inférieur | L8: =MIN(F8,MIN(N($I8)*Paramètres!$C$16,Paramètres!$D$16))+MIN(G8,MIN(N($I8)*Paramètres!$C$17,Paramètres!$D$17))+MIN(H8,MIN(N($I8)*Paramètres!$C$18,Paramètres!$D$18)) -> 40794 | M8: =MIN(N($I8),Paramètres!$C$7)*Paramètres!$C$6 -> 7479.065 | N8: =MIN(M8,E8*Paramètres!$C$8) -> 7479.065 | O8: =E8*IF(K8="Cadre supérieur",Paramètres!$C$10,Paramètres!$C$9) -> 23797.25 | P8: =MAX(0,ROUNDDOWN(N($I8)-L8-N8-O8,-2)) -> 63900 | Q8: =SUMPRODUCT((P8>Paramètres!$B$21:$B$27)*(P8-Paramètres!$B$21:$B$27)*Paramètres!$E$21:$E$27) -> 4352.1 | R8: =Q8*INDEX(Paramètres!$C$31:$C$38,MIN(MAX(INT(N(J8)),0),7)+1) -> 0 | S8: =ROUND(Q8-R8,0) -> 4352 | T8: =ROUND(N($I8)*Paramètres!$C$13,0) -> 4079 | U8: =ROUND(MAX(0,N($I8)-(Q8-R8)-M8)*Paramètres!$C$12,0) -> 1242 | V8: =ROUND(N($I8)-M8-S8-U8,0) -> 122910
B9: 3 | C9: BARRO Yacouba | D9: 46000 | E9: =+I9-(F9+G9+H9) -> 124172 | F9: =MIN(ROUNDDOWN(N($I9)*Paramètres!$C$16,0),Paramètres!$D$16) -> 35477 | G9: =MIN(ROUNDDOWN(N($I9)*Paramètres!$C$17,0),Paramètres!$D$17) -> 8869 | H9: =MIN(ROUNDDOWN(N($I9)*Paramètres!$C$18,0),Paramètres!$D$18) -> 8869 | I9: 177387 | J9: 0 | K9: =IF(E9<Paramètres!$C$11,"Cadre inférieur","Cadre supérieur") -> Cadre inférieur | L9: =MIN(F9,MIN(N($I9)*Paramètres!$C$16,Paramètres!$D$16))+MIN(G9,MIN(N($I9)*Paramètres!$C$17,Paramètres!$D$17))+MIN(H9,MIN(N($I9)*Paramètres!$C$18,Paramètres!$D$18)) -> 53215 | M9: =MIN(N($I9),Paramètres!$C$7)*Paramètres!$C$6 -> 9756.285 | N9: =MIN(M9,E9*Paramètres!$C$8) -> 9756.285 | O9: =E9*IF(K9="Cadre supérieur",Paramètres!$C$10,Paramètres!$C$9) -> 31043 | P9: =MAX(0,ROUNDDOWN(N($I9)-L9-N9-O9,-2)) -> 83300 | Q9: =SUMPRODUCT((P9>Paramètres!$B$21:$B$27)*(P9-Paramètres!$B$21:$B$27)*Paramètres!$E$21:$E$27) -> 7108.1 | R9: =Q9*INDEX(Paramètres!$C$31:$C$38,MIN(MAX(INT(N(J9)),0),7)+1) -> 0 | S9: =ROUND(Q9-R9,0) -> 7108 | T9: =ROUND(N($I9)*Paramètres!$C$13,0) -> 5322 | U9: =ROUND(MAX(0,N($I9)-(Q9-R9)-M9)*Paramètres!$C$12,0) -> 1605 | V9: =ROUND(N($I9)-M9-S9-U9,0) -> 158918
B10: 4 | C10: BASSOLE Ines | D10: 45677 | E10: =+I10-(F10+G10+H10) -> 242562 | F10: =MIN(ROUNDDOWN(N($I10)*Paramètres!$C$16,0),Paramètres!$D$16) -> 69303 | G10: =MIN(ROUNDDOWN(N($I10)*Paramètres!$C$17,0),Paramètres!$D$17) -> 17325 | H10: =MIN(ROUNDDOWN(N($I10)*Paramètres!$C$18,0),Paramètres!$D$18) -> 17325 | I10: 346515 | J10: 0 | K10: =IF(E10<Paramètres!$C$11,"Cadre inférieur","Cadre supérieur") -> Cadre supérieur | L10: =MIN(F10,MIN(N($I10)*Paramètres!$C$16,Paramètres!$D$16))+MIN(G10,MIN(N($I10)*Paramètres!$C$17,Paramètres!$D$17))+MIN(H10,MIN(N($I10)*Paramètres!$C$18,Paramètres!$D$18)) -> 103953 | M10: =MIN(N($I10),Paramètres!$C$7)*Paramètres!$C$6 -> 19058.325 | N10: =MIN(M10,E10*Paramètres!$C$8) -> 19058.325 | O10: =E10*IF(K10="Cadre supérieur",Paramètres!$C$10,Paramètres!$C$9) -> 48512.4 | P10: =MAX(0,ROUNDDOWN(N($I10)-L10-N10-O10,-2)) -> 174900 | Q10: =SUMPRODUCT((P10>Paramètres!$B$21:$B$27)*(P10-Paramètres!$B$21:$B$27)*Paramètres!$E$21:$E$27) -> 23133.3 | R10: =Q10*INDEX(Paramètres!$C$31:$C$38,MIN(MAX(INT(N(J10)),0),7)+1) -> 0 | S10: =ROUND(Q10-R10,0) -> 23133 | T10: =ROUND(N($I10)*Paramètres!$C$13,0) -> 10395 | U10: =ROUND(MAX(0,N($I10)-(Q10-R10)-M10)*Paramètres!$C$12,0) -> 3043 | V10: =ROUND(N($I10)-M10-S10-U10,0) -> 301281
B11: 5 | C11: BAWAR B. Fulgence | D11: 46023 | E11: =+I11-(F11+G11+H11) -> 115738 | F11: =MIN(ROUNDDOWN(N($I11)*Paramètres!$C$16,0),Paramètres!$D$16) -> 33068 | G11: =MIN(ROUNDDOWN(N($I11)*Paramètres!$C$17,0),Paramètres!$D$17) -> 8267 | H11: =MIN(ROUNDDOWN(N($I11)*Paramètres!$C$18,0),Paramètres!$D$18) -> 8267 | I11: 165340 | J11: 0 | K11: =IF(E11<Paramètres!$C$11,"Cadre inférieur","Cadre supérieur") -> Cadre inférieur | L11: =MIN(F11,MIN(N($I11)*Paramètres!$C$16,Paramètres!$D$16))+MIN(G11,MIN(N($I11)*Paramètres!$C$17,Paramètres!$D$17))+MIN(H11,MIN(N($I11)*Paramètres!$C$18,Paramètres!$D$18)) -> 49602 | M11: =MIN(N($I11),Paramètres!$C$7)*Paramètres!$C$6 -> 9093.7 | N11: =MIN(M11,E11*Paramètres!$C$8) -> 9093.7 | O11: =E11*IF(K11="Cadre supérieur",Paramètres!$C$10,Paramètres!$C$9) -> 28934.5 | P11: =MAX(0,ROUNDDOWN(N($I11)-L11-N11-O11,-2)) -> 77700 | Q11: =SUMPRODUCT((P11>Paramètres!$B$21:$B$27)*(P11-Paramètres!$B$21:$B$27)*Paramètres!$E$21:$E$27) -> 6270.3 | R11: =Q11*INDEX(Paramètres!$C$31:$C$38,MIN(MAX(INT(N(J11)),0),7)+1) -> 0 | S11: =ROUND(Q11-R11,0) -> 6270 | T11: =ROUND(N($I11)*Paramètres!$C$13,0) -> 4960 | U11: =ROUND(MAX(0,N($I11)-(Q11-R11)-M11)*Paramètres!$C$12,0) -> 1500 | V11: =ROUND(N($I11)-M11-S11-U11,0) -> 148476
B12: 6 | C12: BAZIE Issouf | D12: 46217 | E12: =+I12-(F12+G12+H12) -> 124172 | F12: =MIN(ROUNDDOWN(N($I12)*Paramètres!$C$16,0),Paramètres!$D$16) -> 35477 | G12: =MIN(ROUNDDOWN(N($I12)*Paramètres!$C$17,0),Paramètres!$D$17) -> 8869 | H12: =MIN(ROUNDDOWN(N($I12)*Paramètres!$C$18,0),Paramètres!$D$18) -> 8869 | I12: 177387 | J12: 0 | K12: =IF(E12<Paramètres!$C$11,"Cadre inférieur","Cadre supérieur") -> Cadre inférieur | L12: =MIN(F12,MIN(N($I12)*Paramètres!$C$16,Paramètres!$D$16))+MIN(G12,MIN(N($I12)*Paramètres!$C$17,Paramètres!$D$17))+MIN(H12,MIN(N($I12)*Paramètres!$C$18,Paramètres!$D$18)) -> 53215 | M12: =MIN(N($I12),Paramètres!$C$7)*Paramètres!$C$6 -> 9756.285 | N12: =MIN(M12,E12*Paramètres!$C$8) -> 9756.285 | O12: =E12*IF(K12="Cadre supérieur",Paramètres!$C$10,Paramètres!$C$9) -> 31043 | P12: =MAX(0,ROUNDDOWN(N($I12)-L12-N12-O12,-2)) -> 83300 | Q12: =SUMPRODUCT((P12>Paramètres!$B$21:$B$27)*(P12-Paramètres!$B$21:$B$27)*Paramètres!$E$21:$E$27) -> 7108.1 | R12: =Q12*INDEX(Paramètres!$C$31:$C$38,MIN(MAX(INT(N(J12)),0),7)+1) -> 0 | S12: =ROUND(Q12-R12,0) -> 7108 | T12: =ROUND(N($I12)*Paramètres!$C$13,0) -> 5322 | U12: =ROUND(MAX(0,N($I12)-(Q12-R12)-M12)*Paramètres!$C$12,0) -> 1605 | V12: =ROUND(N($I12)-M12-S12-U12,0) -> 158918
B13: 7 | C13: BELEM Abdoulaye | D13: 46174 | E13: =+I13-(F13+G13+H13) -> 136840 | F13: =MIN(ROUNDDOWN(N($I13)*Paramètres!$C$16,0),Paramètres!$D$16) -> 39096 | G13: =MIN(ROUNDDOWN(N($I13)*Paramètres!$C$17,0),Paramètres!$D$17) -> 9774 | H13: =MIN(ROUNDDOWN(N($I13)*Paramètres!$C$18,0),Paramètres!$D$18) -> 9774 | I13: 195484 | J13: 0 | K13: =IF(E13<Paramètres!$C$11,"Cadre inférieur","Cadre supérieur") -> Cadre inférieur | L13: =MIN(F13,MIN(N($I13)*Paramètres!$C$16,Paramètres!$D$16))+MIN(G13,MIN(N($I13)*Paramètres!$C$17,Paramètres!$D$17))+MIN(H13,MIN(N($I13)*Paramètres!$C$18,Paramètres!$D$18)) -> 58644 | M13: =MIN(N($I13),Paramètres!$C$7)*Paramètres!$C$6 -> 10751.62 | N13: =MIN(M13,E13*Paramètres!$C$8) -> 10751.62 | O13: =E13*IF(K13="Cadre supérieur",Paramètres!$C$10,Paramètres!$C$9) -> 34210 | P13: =MAX(0,ROUNDDOWN(N($I13)-L13-N13-O13,-2)) -> 91800 | Q13: =SUMPRODUCT((P13>Paramètres!$B$21:$B$27)*(P13-Paramètres!$B$21:$B$27)*Paramètres!$E$21:$E$27) -> 8442.6 | R13: =Q13*INDEX(Paramètres!$C$31:$C$38,MIN(MAX(INT(N(J13)),0),7)+1) -> 0 | S13: =ROUND(Q13-R13,0) -> 8443 | T13: =ROUND(N($I13)*Paramètres!$C$13,0) -> 5865 | U13: =ROUND(MAX(0,N($I13)-(Q13-R13)-M13)*Paramètres!$C$12,0) -> 1763 | V13: =ROUND(N($I13)-M13-S13-U13,0) -> 174526
B14: 8 | C14: BENAO Souleymane | D14: 45778 | E14: =+I14-(F14+G14+H14) -> 149497 | F14: =MIN(ROUNDDOWN(N($I14)*Paramètres!$C$16,0),Paramètres!$D$16) -> 42713 | G14: =MIN(ROUNDDOWN(N($I14)*Paramètres!$C$17,0),Paramètres!$D$17) -> 10678 | H14: =MIN(ROUNDDOWN(N($I14)*Paramètres!$C$18,0),Paramètres!$D$18) -> 10678 | I14: 213566 | J14: 0 | K14: =IF(E14<Paramètres!$C$11,"Cadre inférieur","Cadre supérieur") -> Cadre inférieur | L14: =MIN(F14,MIN(N($I14)*Paramètres!$C$16,Paramètres!$D$16))+MIN(G14,MIN(N($I14)*Paramètres!$C$17,Paramètres!$D$17))+MIN(H14,MIN(N($I14)*Paramètres!$C$18,Paramètres!$D$18)) -> 64069 | M14: =MIN(N($I14),Paramètres!$C$7)*Paramètres!$C$6 -> 11746.13 | N14: =MIN(M14,E14*Paramètres!$C$8) -> 11746.13 | O14: =E14*IF(K14="Cadre supérieur",Paramètres!$C$10,Paramètres!$C$9) -> 37374.25 | P14: =MAX(0,ROUNDDOWN(N($I14)-L14-N14-O14,-2)) -> 100300 | Q14: =SUMPRODUCT((P14>Paramètres!$B$21:$B$27)*(P14-Paramètres!$B$21:$B$27)*Paramètres!$E$21:$E$27) -> 9777.1 | R14: =Q14*INDEX(Paramètres!$C$31:$C$38,MIN(MAX(INT(N(J14)),0),7)+1) -> 0 | S14: =ROUND(Q14-R14,0) -> 9777 | T14: =ROUND(N($I14)*Paramètres!$C$13,0) -> 6407 | U14: =ROUND(MAX(0,N($I14)-(Q14-R14)-M14)*Paramètres!$C$12,0) -> 1920 | V14: =ROUND(N($I14)-M14-S14-U14,0) -> 190123
B15: 9 | C15: BILOGO Aline | D15: 46250 | E15: =+I15-(F15+G15+H15) -> 115738 | F15: =MIN(ROUNDDOWN(N($I15)*Paramètres!$C$16,0),Paramètres!$D$16) -> 33068 | G15: =MIN(ROUNDDOWN(N($I15)*Paramètres!$C$17,0),Paramètres!$D$17) -> 8267 | H15: =MIN(ROUNDDOWN(N($I15)*Paramètres!$C$18,0),Paramètres!$D$18) -> 8267 | I15: 165340 | J15: 0 | K15: =IF(E15<Paramètres!$C$11,"Cadre inférieur","Cadre supérieur") -> Cadre inférieur | L15: =MIN(F15,MIN(N($I15)*Paramètres!$C$16,Paramètres!$D$16))+MIN(G15,MIN(N($I15)*Paramètres!$C$17,Paramètres!$D$17))+MIN(H15,MIN(N($I15)*Paramètres!$C$18,Paramètres!$D$18)) -> 49602 | M15: =MIN(N($I15),Paramètres!$C$7)*Paramètres!$C$6 -> 9093.7 | N15: =MIN(M15,E15*Paramètres!$C$8) -> 9093.7 | O15: =E15*IF(K15="Cadre supérieur",Paramètres!$C$10,Paramètres!$C$9) -> 28934.5 | P15: =MAX(0,ROUNDDOWN(N($I15)-L15-N15-O15,-2)) -> 77700 | Q15: =SUMPRODUCT((P15>Paramètres!$B$21:$B$27)*(P15-Paramètres!$B$21:$B$27)*Paramètres!$E$21:$E$27) -> 6270.3 | R15: =Q15*INDEX(Paramètres!$C$31:$C$38,MIN(MAX(INT(N(J15)),0),7)+1) -> 0 | S15: =ROUND(Q15-R15,0) -> 6270 | T15: =ROUND(N($I15)*Paramètres!$C$13,0) -> 4960 | U15: =ROUND(MAX(0,N($I15)-(Q15-R15)-M15)*Paramètres!$C$12,0) -> 1500 | V15: =ROUND(N($I15)-M15-S15-U15,0) -> 148476
B16: 10 | C16: BONKOUNGOU Judicael | D16: 45778 | E16: =+I16-(F16+G16+H16) -> 149495 | F16: =MIN(ROUNDDOWN(N($I16)*Paramètres!$C$16,0),Paramètres!$D$16) -> 42712 | G16: =MIN(ROUNDDOWN(N($I16)*Paramètres!$C$17,0),Paramètres!$D$17) -> 10678 | H16: =MIN(ROUNDDOWN(N($I16)*Paramètres!$C$18,0),Paramètres!$D$18) -> 10678 | I16: 213563 | J16: 0 | K16: =IF(E16<Paramètres!$C$11,"Cadre inférieur","Cadre supérieur") -> Cadre inférieur | L16: =MIN(F16,MIN(N($I16)*Paramètres!$C$16,Paramètres!$D$16))+MIN(G16,MIN(N($I16)*Paramètres!$C$17,Paramètres!$D$17))+MIN(H16,MIN(N($I16)*Paramètres!$C$18,Paramètres!$D$18)) -> 64068 | M16: =MIN(N($I16),Paramètres!$C$7)*Paramètres!$C$6 -> 11745.965 | N16: =MIN(M16,E16*Paramètres!$C$8) -> 11745.965 | O16: =E16*IF(K16="Cadre supérieur",Paramètres!$C$10,Paramètres!$C$9) -> 37373.75 | P16: =MAX(0,ROUNDDOWN(N($I16)-L16-N16-O16,-2)) -> 100300 | Q16: =SUMPRODUCT((P16>Paramètres!$B$21:$B$27)*(P16-Paramètres!$B$21:$B$27)*Paramètres!$E$21:$E$27) -> 9777.1 | R16: =Q16*INDEX(Paramètres!$C$31:$C$38,MIN(MAX(INT(N(J16)),0),7)+1) -> 0 | S16: =ROUND(Q16-R16,0) -> 9777 | T16: =ROUND(N($I16)*Paramètres!$C$13,0) -> 6407 | U16: =ROUND(MAX(0,N($I16)-(Q16-R16)-M16)*Paramètres!$C$12,0) -> 1920 | V16: =ROUND(N($I16)-M16-S16-U16,0) -> 190120
B17: 11 | C17: BONKOUNGOU Moussa | D17: 45778 | E17: =+I17-(F17+G17+H17) -> 149495 | F17: =MIN(ROUNDDOWN(N($I17)*Paramètres!$C$16,0),Paramètres!$D$16) -> 42712 | G17: =MIN(ROUNDDOWN(N($I17)*Paramètres!$C$17,0),Paramètres!$D$17) -> 10678 | H17: =MIN(ROUNDDOWN(N($I17)*Paramètres!$C$18,0),Paramètres!$D$18) -> 10678 | I17: 213563 | J17: 0 | K17: =IF(E17<Paramètres!$C$11,"Cadre inférieur","Cadre supérieur") -> Cadre inférieur | L17: =MIN(F17,MIN(N($I17)*Paramètres!$C$16,Paramètres!$D$16))+MIN(G17,MIN(N($I17)*Paramètres!$C$17,Paramètres!$D$17))+MIN(H17,MIN(N($I17)*Paramètres!$C$18,Paramètres!$D$18)) -> 64068 | M17: =MIN(N($I17),Paramètres!$C$7)*Paramètres!$C$6 -> 11745.965 | N17: =MIN(M17,E17*Paramètres!$C$8) -> 11745.965 | O17: =E17*IF(K17="Cadre supérieur",Paramètres!$C$10,Paramètres!$C$9) -> 37373.75 | P17: =MAX(0,ROUNDDOWN(N($I17)-L17-N17-O17,-2)) -> 100300 | Q17: =SUMPRODUCT((P17>Paramètres!$B$21:$B$27)*(P17-Paramètres!$B$21:$B$27)*Paramètres!$E$21:$E$27) -> 9777.1 | R17: =Q17*INDEX(Paramètres!$C$31:$C$38,MIN(MAX(INT(N(J17)),0),7)+1) -> 0 | S17: =ROUND(Q17-R17,0) -> 9777 | T17: =ROUND(N($I17)*Paramètres!$C$13,0) -> 6407 | U17: =ROUND(MAX(0,N($I17)-(Q17-R17)-M17)*Paramètres!$C$12,0) -> 1920 | V17: =ROUND(N($I17)-M17-S17-U17,0) -> 190120
