Workbook

Sheet Jan-fév-mars-avril-mai-juin
B2: ETAT DES SALAIRES KS SARL
B3: Période: | D3: JUILLET - AOUT - SEPTEMBRE 2026
B4: N° | C4: Nom&Prénom | D4: DATE D'ENTREE | E4: 46023 | F4: 46054 | G4: 46082 | H4: 46113 | I4: 46143 | J4: 46174
B5: 1 | C5: OUEDRAOGO Abdoul Ganiyou | D5: 45881 | E5: 165340 | F5: 225778 | G5: 225778 | H5: 225778 | I5: 225778 | J5: 346515
B6: 2 | C6: OUEDRAOGO Mohamed | D6: 45778 | E6: 0 | F6: 0 | G6: 213563 | H6: 213563 | I6: 213563 | J6: 225778
B7: 3 | C7: SAWADOGO Ibrahim | D7: 45912 | E7: 0 | F7: 0 | G7: 213566 | H7: 213566 | I7: 213566 | J7: 225778
B8: 4 | C8: SALO Arouna | D8: 45778 | E8: 0 | F8: 0 | G8: 0 | H8: 213566 | I8: 213566 | J8: 213566
B9: 5 | C9: ILBOUDO Jean Marie | D9: 46000 | E9: 0 | F9: 0 | G9: 0 | H9: 177387 | I9: 177387 | J9: 177387
B10: 6 | C10: KOMPAORE Anicet | D10: 45778 | E10: 165340 | F10: 225778 | G10: 225778 | H10: 225778 | I10: 225778 | J10: 225778
B11: 7 | C11: BASSOLE Ines | D11: 45677 | E11: 286055 | F11: 286055 | G11: 286055 | H11: 286055 | I11: 346515 | J11: 346515
B12: 8 | C12: KABRE Ali | D12: 45677 | E12: 286055 | F12: 286055 | G12: 286055 | H12: 286055 | I12: 346515 | J12: 346515
B13: 9 | C13: KABRE Esther | D13: 46092 | E13: 0 | F13: 0 | G13: 135983 | H13: 135983 | I13: 165340 | J13: 165340
B14: Total par mois | E14: =SUM(E5:E13) -> 902790 | F14: =SUM(F5:F13) -> 1023666 | G14: =SUM(G5:G13) -> 1586778 | H14: =SUM(H5:H13) -> 1977731 | I14: =SUM(I5:I13) -> 2128008 | J14: =SUM(J5:J13) -> 2273172
B15: CUMUL | E15: =SUM(E14:J14) -> 9892145

Sheet Juill-aout-sept 2026
B2: ETAT DES SALAIRES KS SARL
B3: Période: | D3: JUILLET - AOUT - SEPTEMBRE 2026
B4: N° | C4: Nom&Prénom | D4: DATE D'ENTREE | E4: 46204 | F4: 46235 | G4: 46266
B5: 1 | C5: BAGAGNAN Salima | D5: 46242 | E5: 0 | F5: 80000 | G5: 80000
B6: 2 | C6: BANHORO Adama | D6: 46196 | E6: 0 | F6: 135983 | G6: 135983
B7: 3 | C7: BARRO Yacouba | D7: 46000 | E7: 177387 | F7: 177387 | G7: 177387
B8: 4 | C8: BASSOLE Ines | D8: 45677 | E8: 346515 | F8: 346515 | G8: 346515
B9: 5 | C9: BAWAR B. Fulgence | D9: 46023 | E9: 165340 | F9: 165340 | G9: 165340
B10: 6 | C10: BAZIE Issouf | D10: 46217 | E10: 0 | F10: 177387 | G10: 177387
B11: 7 | C11: BELEM Abdoulaye | D11: 46174 | E11: 195484 | F11: 195484 | G11: 195484
B12: 8 | C12: BENAO Souleymane | D12: 45778 | E12: 213566 | F12: 213566 | G12: 213566
B13: 9 | C13: BILOGO Aline | D13: 46250 | E13: 0 | F13: 165340 | G13: 225778
B14: 10 | C14: BONKOUNGOU Judicael | D14: 45778 | E14: 213563 | F14: 213563 | G14: 213563
B15: 11 | C15: BONKOUNGOU Moussa | D15: 45778 | E15: 213563 | F15: 213563 | G15: 213563
B16: 12 | C16: BOUKARI Amidou | D16: 46183 | E16: 80000 | F16: 177387 | G16: 177387
C17: COULIBALY Ahmed | E17: 0 | F17: 0 | G17: 0
B18: 13 | C18: DIABATE Mohamed | D18: 45950 | E18: 177387 | F18: 177387 | G18: 177387
B19: 14 | C19: DIALLO Boureima | D19: 46183 | E19: 0 | F19: 177387 | G19: 177387
B20: 15 | C20: GANSONRE Alassane | D20: 46139 | E20: 135983 | F20: 135983 | G20: 135983
B21: 16 | C21: GOUBA Simon | D21: 45809 | E21: 135983 | F21: 135983 | G21: 135983
B22: 17 | C22: GOULLA Parbouré | D22: 46174 | E22: 0 | F22: 177387 | G22: 177387
B23: 18 | C23: GUIGUEMDE CALEB | D23: 45924 | E23: 0 | F23: 0 | G23: 177387
B24: 19 | C24: ILBOUDO Alassane | D24: 46216 | E24: 135983 | F24: 225778 | G24: 225778
B25: 20 | C25: ILBOUDO Jean Marie | D25: 46000 | E25: 177387 | F25: 177387 | G25: 177387
B26: 21 | C26: ILBOUDO Zakaria | D26: 46283 | E26: 0 | F26: 0 | G26: 81666
B27: 22 | C27: KABORE Abdoulaye | D27: 46204 | E27: 231913 | F27: 231913 | G27: 213566
B28: 23 | C28: KABORE Dramane | D28: 0107/2026 | E28: 0 | F28: 177387 | G28: 177387
B29: 24 | C29: KABORE Lassane | D29: 45778 | E29: 165340 | F29: 165340 | G29: 165340
B30: 25 | C30: KABORE Sid Mohamed | D30: 46183 | E30: 80000 | F30: 177387 | G30: 177387
C31: KABRE Ali | E31: 346515 | F31: 346515 | G31: 346515
B32: 26 | C32: KABRE Daouda | D32: 45965 | E32: 0 | F32: 165340 | G32: 80000
B33: 27 | C33: KABRE Esther | D33: 46092 | E33: 165340 | F33: 225778 | G33: 225778
C34: KARAMA Youmati | E34: 195448 | F34: 0 | G34: 0
B35: 28 | C35: KAZIENGA PascaL | D35: 46275 | E35: 0 | F35: 0 | G35: 108397
B36: 29 | C36: KOANDA Souleymane | D36: 46216 | E36: 135983 | F36: 225778 | G36: 225778
B37: 30 | C37: KOMPAORE Anicet | D37: 45778 | E37: 346515 | F37: 346515 | G37: 346515
B38: 31 | C38: KONE Tidiane | D38: 45962 | E38: 213563 | F38: 213563 | G38: 213563
B39: 32 | C39: KONSIMBO A. Aziz | D39: 46252 | E39: 0 | F39: 0 | G39: 135983
B40: 33 | C40: MAIGA Harisso | D40: 46023 | E40: 213563 | F40: 213563 | G40: 213566
B41: 34 | C41: NANEMA Roger | D41: 46220 | E41: 0 | F41: 195448 | G41: 256095
...

Sheet Janvier
B4: ETAT DES SALAIRES KS SARL
B5: Période: | D5: JANVIER 2026 | F5: Ventilation simulée (max. exonéré) | J5: Hypothèses | L5: Calcul IUTS | T5: TPA, Rosalaire et net
B6: N° | C6: Nom&Prénom | D6: DATE D'ENTREE | E6: Brut Janvier | F6: Ind. Logement | G6: Ind. Transport | H6: Ind. Fonction | I6: Salaire de base | J6: Nb charges | K6: Catégorie | L6: Montant exonéré | M6: CNSS salarié 5,5 % | N6: Déduction retraite | O6: Abattement forfaitaire | P6: Base imposable (arr. 100) | Q6: IUTS brut | R6: Réduction charges | S6: IUTS NET | T6: TPA 3 % (patronale) | U6: Rosalaire 1 % | V6: SALAIRE NET À PAYER
B7: 1 | C7: OUEDRAOGO Abdoul Ganiyou | D7: 45881 | E7: ='Jan-fév-mars-avril-mai-juin'!E5 -> 165340 | F7: =MIN(ROUNDDOWN(N($E7)*Paramètres!$C$16,0),Paramètres!$D$16) -> 33068 | G7: =MIN(ROUNDDOWN(N($E7)*Paramètres!$C$17,0),Paramètres!$D$17) -> 8267 | H7: =MIN(ROUNDDOWN(N($E7)*Paramètres!$C$18,0),Paramètres!$D$18) -> 8267 | I7: =N($E7)-(F7+G7+H7) -> 115738 | J7: 0 | K7: =IF(I7<Paramètres!$C$11,"Cadre inférieur","Cadre supérieur") -> Cadre inférieur | L7: =MIN(F7,MIN(N($E7)*Paramètres!$C$16,Paramètres!$D$16))+MIN(G7,MIN(N($E7)*Paramètres!$C$17,Paramètres!$D$17))+MIN(H7,MIN(N($E7)*Paramètres!$C$18,Paramètres!$D$18)) -> 49602 | M7: =MIN(N($E7),Paramètres!$C$7)*Paramètres!$C$6 -> 9093.7 | N7: =MIN(M7,I7*Paramètres!$C$8) -> 9093.7 | O7: =I7*IF(K7="Cadre supérieur",Paramètres!$C$10,Paramètres!$C$9) -> 28934.5 | P7: =MAX(0,ROUNDDOWN(N($E7)-L7-N7-O7,-2)) -> 77700 | Q7: =SUMPRODUCT((P7>Paramètres!$B$21:$B$27)*(P7-Paramètres!$B$21:$B$27)*Paramètres!$E$21:$E$27) -> 6270.3 | R7: =Q7*INDEX(Paramètres!$C$31:$C$38,MIN(MAX(INT(N(J7)),0),7)+1) -> 0 | S7: =ROUND(Q7-R7,0) -> 6270 | T7: =ROUND(N($E7)*Paramètres!$C$13,0) -> 4960 | U7: =ROUND(MAX(0,N($E7)-(Q7-R7)-M7)*Paramètres!$C$12,0) -> 1500 | V7: =ROUND(N($E7)-M7-S7-U7,0) -> 148476
B8: 2 | C8: OUEDRAOGO Mohamed | D8: 45778 | E8: ='Jan-fév-mars-avril-mai-juin'!E6 -> 0 | F8: =MIN(ROUNDDOWN(N($E8)*Paramètres!$C$16,0),Paramètres!$D$16) -> 0 | G8: =MIN(ROUNDDOWN(N($E8)*Paramètres!$C$17,0),Paramètres!$D$17) -> 0 | H8: =MIN(ROUNDDOWN(N($E8)*Paramètres!$C$18,0),Paramètres!$D$18) -> 0 | I8: =N($E8)-(F8+G8+H8) -> 0 | J8: 0 | K8: =IF(I8<Paramètres!$C$11,"Cadre inférieur","Cadre supérieur") -> Cadre inférieur | L8: =MIN(F8,MIN(N($E8)*Paramètres!$C$16,Paramètres!$D$16))+MIN(G8,MIN(N($E8)*Paramètres!$C$17,Paramètres!$D$17))+MIN(H8,MIN(N($E8)*Paramètres!$C$18,Paramètres!$D$18)) -> 0 | M8: =MIN(N($E8),Paramètres!$C$7)*Paramètres!$C$6 -> 0 | N8: =MIN(M8,I8*Paramètres!$C$8) -> 0 | O8: =I8*IF(K8="Cadre supérieur",Paramètres!$C$10,Paramètres!$C$9) -> 0 | P8: =MAX(0,ROUNDDOWN(N($E8)-L8-N8-O8,-2)) -> 0 | Q8: =SUMPRODUCT((P8>Paramètres!$B$21:$B$27)*(P8-Paramètres!$B$21:$B$27)*Paramètres!$E$21:$E$27) -> 0 | R8: =Q8*INDEX(Paramètres!$C$31:$C$38,MIN(MAX(INT(N(J8)),0),7)+1) -> 0 | S8: =ROUND(Q8-R8,0) -> 0 | T8: =ROUND(N($E8)*Paramètres!$C$13,0) -> 0 | U8: =ROUND(MAX(0,N($E8)-(Q8-R8)-M8)*Paramètres!$C$12,0) -> 0 | V8: =ROUND(N($E8)-M8-S8-U8,0) -> 0
B9: 3 | C9: SAWADOGO Ibrahim | D9: 45912 | E9: ='Jan-fév-mars-avril-mai-juin'!E7 -> 0 | F9: =MIN(ROUNDDOWN(N($E9)*Paramètres!$C$16,0),Paramètres!$D$16) -> 0 | G9: =MIN(ROUNDDOWN(N($E9)*Paramètres!$C$17,0),Paramètres!$D$17) -> 0 | H9: =MIN(ROUNDDOWN(N($E9)*Paramètres!$C$18,0),Paramètres!$D$18) -> 0 | I9: =N($E9)-(F9+G9+H9) -> 0 | J9: 0 | K9: =IF(I9<Paramètres!$C$11,"Cadre inférieur","Cadre supérieur") -> Cadre inférieur | L9: =MIN(F9,MIN(N($E9)*Paramètres!$C$16,Paramètres!$D$16))+MIN(G9,MIN(N($E9)*Paramètres!$C$17,Paramètres!$D$17))+MIN(H9,MIN(N($E9)*Paramètres!$C$18,Paramètres!$D$18)) -> 0 | M9: =MIN(N($E9),Paramètres!$C$7)*Paramètres!$C$6 -> 0 | N9: =MIN(M9,I9*Paramètres!$C$8) -> 0 | O9: =I9*IF(K9="Cadre supérieur",Paramètres!$C$10,Paramètres!$C$9) -> 0 | P9: =MAX(0,ROUNDDOWN(N($E9)-L9-N9-O9,-2)) -> 0 | Q9: =SUMPRODUCT((P9>Paramètres!$B$21:$B$27)*(P9-Paramètres!$B$21:$B$27)*Paramètres!$E$21:$E$27) -> 0 | R9: =Q9*INDEX(Paramètres!$C$31:$C$38,MIN(MAX(INT(N(J9)),0),7)+1) -> 0 | S9: =ROUND(Q9-R9,0) -> 0 | T9: =ROUND(N($E9)*Paramètres!$C$13,0) -> 0 | U9: =ROUND(MAX(0,N($E9)-(Q9-R9)-M9)*Paramètres!$C$12,0) -> 0 | V9: =ROUND(N($E9)-M9-S9-U9,0) -> 0
B10: 4 | C10: SALO Arouna | D10: 45778 | E10: ='Jan-fév-mars-avril-mai-juin'!E8 -> 0 | F10: =MIN(ROUNDDOWN(N($E10)*Paramètres!$C$16,0),Paramètres!$D$16) -> 0 | G10: =MIN(ROUNDDOWN(N($E10)*Paramètres!$C$17,0),Paramètres!$D$17) -> 0 | H10: =MIN(ROUNDDOWN(N($E10)*Paramètres!$C$18,0),Paramètres!$D$18) -> 0 | I10: =N($E10)-(F10+G10+H10) -> 0 | J10: 0 | K10: =IF(I10<Paramètres!$C$11,"Cadre inférieur","Cadre supérieur") -> Cadre inférieur | L10: =MIN(F10,MIN(N($E10)*Paramètres!$C$16,Paramètres!$D$16))+MIN(G10,MIN(N($E10)*Paramètres!$C$17,Paramètres!$D$17))+MIN(H10,MIN(N($E10)*Paramètres!$C$18,Paramètres!$D$18)) -> 0 | M10: =MIN(N($E10),Paramètres!$C$7)*Paramètres!$C$6 -> 0 | N10: =MIN(M10,I10*Paramètres!$C$8) -> 0 | O10: =I10*IF(K10="Cadre supérieur",Paramètres!$C$10,Paramètres!$C$9) -> 0 | P10: =MAX(0,ROUNDDOWN(N($E10)-L10-N10-O10,-2)) -> 0 | Q10: =SUMPRODUCT((P10>Paramètres!$B$21:$B$27)*(P10-Paramètres!$B$21:$B$27)*Paramètres!$E$21:$E$27) -> 0 | R10: =Q10*INDEX(Paramètres!$C$31:$C$38,MIN(MAX(INT(N(J10)),0),7)+1) -> 0 | S10: =ROUND(Q10-R10,0) -> 0 | T10: =ROUND(N($E10)*Paramètres!$C$13,0) -> 0 | U10: =ROUND(MAX(0,N($E10)-(Q10-R10)-M10)*Paramètres!$C$12,0) -> 0 | V10: =ROUND(N($E10)-M10-S10-U10,0) -> 0
B11: 5 | C11: ILBOUDO Jean Marie | D11: 46000 | E11: ='Jan-fév-mars-avril-mai-juin'!E9 -> 0 | F11: =MIN(ROUNDDOWN(N($E11)*Paramètres!$C$16,0),Paramètres!$D$16) -> 0 | G11: =MIN(ROUNDDOWN(N($E11)*Paramètres!$C$17,0),Paramètres!$D$17) -> 0 | H11: =MIN(ROUNDDOWN(N($E11)*Paramètres!$C$18,0),Paramètres!$D$18) -> 0 | I11: =N($E11)-(F11+G11+H11) -> 0 | J11: 0 | K11: =IF(I11<Paramètres!$C$11,"Cadre inférieur","Cadre supérieur") -> Cadre inférieur | L11: =MIN(F11,MIN(N($E11)*Paramètres!$C$16,Paramètres!$D$16))+MIN(G11,MIN(N($E11)*Paramètres!$C$17,Paramètres!$D$17))+MIN(H11,MIN(N($E11)*Paramètres!$C$18,Paramètres!$D$18)) -> 0 | M11: =MIN(N($E11),Paramètres!$C$7)*Paramètres!$C$6 -> 0 | N11: =MIN(M11,I11*Paramètres!$C$8) -> 0 | O11: =I11*IF(K11="Cadre supérieur",Paramètres!$C$10,Paramètres!$C$9) -> 0 | P11: =MAX(0,ROUNDDOWN(N($E11)-L11-N11-O11,-2)) -> 0 | Q11: =SUMPRODUCT((P11>Paramètres!$B$21:$B$27)*(P11-Paramètres!$B$21:$B$27)*Paramètres!$E$21:$E$27) -> 0 | R11: =Q11*INDEX(Paramètres!$C$31:$C$38,MIN(MAX(INT(N(J11)),0),7)+1) -> 0 | S11: =ROUND(Q11-R11,0) -> 0 | T11: =ROUND(N($E11)*Paramètres!$C$13,0) -> 0 | U11: =ROUND(MAX(0,N($E11)-(Q11-R11)-M11)*Paramètres!$C$12,0) -> 0 | V11: =ROUND(N($E11)-M11-S11-U11,0) -> 0
B12: 6 | C12: KOMPAORE Anicet | D12: 45778 | E12: ='Jan-fév-mars-avril-mai-juin'!E10 -> 165340 | F12: =MIN(ROUNDDOWN(N($E12)*Paramètres!$C$16,0),Paramètres!$D$16) -> 33068 | G12: =MIN(ROUNDDOWN(N($E12)*Paramètres!$C$17,0),Paramètres!$D$17) -> 8267 | H12: =MIN(ROUNDDOWN(N($E12)*Paramètres!$C$18,0),Paramètres!$D$18) -> 8267 | I12: =N($E12)-(F12+G12+H12) -> 115738 | J12: 0 | K12: =IF(I12<Paramètres!$C$11,"Cadre inférieur","Cadre supérieur") -> Cadre inférieur | L12: =MIN(F12,MIN(N($E12)*Paramètres!$C$16,Paramètres!$D$16))+MIN(G12,MIN(N($E12)*Paramètres!$C$17,Paramètres!$D$17))+MIN(H12,MIN(N($E12)*Paramètres!$C$18,Paramètres!$D$18)) -> 49602 | M12: =MIN(N($E12),Paramètres!$C$7)*Paramètres!$C$6 -> 9093.7 | N12: =MIN(M12,I12*Paramètres!$C$8) -> 9093.7 | O12: =I12*IF(K12="Cadre supérieur",Paramètres!$C$10,Paramètres!$C$9) -> 28934.5 | P12: =MAX(0,ROUNDDOWN(N($E12)-L12-N12-O12,-2)) -> 77700 | Q12: =SUMPRODUCT((P12>Paramètres!$B$21:$B$27)*(P12-Paramètres!$B$21:$B$27)*Paramètres!$E$21:$E$27) -> 6270.3 | R12: =Q12*INDEX(Paramètres!$C$31:$C$38,MIN(MAX(INT(N(J12)),0),7)+1) -> 0 | S12: =ROUND(Q12-R12,0) -> 6270 | T12: =ROUND(N($E12)*Paramètres!$C$13,0) -> 4960 | U12: =ROUND(MAX(0,N($E12)-(Q12-R12)-M12)*Paramètres!$C$12,0) -> 1500 | V12: =ROUND(N($E12)-M12-S12-U12,0) -> 148476
B13: 7 | C13: BASSOLE Ines | D13: 45677 | E13: ='Jan-fév-mars-avril-mai-juin'!E11 -> 286055 | F13: =MIN(ROUNDDOWN(N($E13)*Paramètres!$C$16,0),Paramètres!$D$16) -> 57211 | G13: =MIN(ROUNDDOWN(N($E13)*Paramètres!$C$17,0),Paramètres!$D$17) -> 14302 | H13: =MIN(ROUNDDOWN(N($E13)*Paramètres!$C$18,0),Paramètres!$D$18) -> 14302 | I13: =N($E13)-(F13+G13+H13) -> 200240 | J13: 0 | K13: =IF(I13<Paramètres!$C$11,"Cadre inférieur","Cadre supérieur") -> Cadre supérieur | L13: =MIN(F13,MIN(N($E13)*Paramètres!$C$16,Paramètres!$D$16))+MIN(G13,MIN(N($E13)*Paramètres!$C$17,Paramètres!$D$17))+MIN(H13,MIN(N($E13)*Paramètres!$C$18,Paramètres!$D$18)) -> 85815 | M13: =MIN(N($E13),Paramètres!$C$7)*Paramètres!$C$6 -> 15733.025 | N13: =MIN(M13,I13*Paramètres!$C$8) -> 15733.025 | O13: =I13*IF(K13="Cadre supérieur",Paramètres!$C$10,Paramètres!$C$9) -> 40048 | P13: =MAX(0,ROUNDDOWN(N($E13)-L13-N13-O13,-2)) -> 144400 | Q13: =SUMPRODUCT((P13>Paramètres!$B$21:$B$27)*(P13-Paramètres!$B$21:$B$27)*Paramètres!$E$21:$E$27) -> 17359.6 | R13: =Q13*INDEX(Paramètres!$C$31:$C$38,MIN(MAX(INT(N(J13)),0),7)+1) -> 0 | S13: =ROUND(Q13-R13,0) -> 17360 | T13: =ROUND(N($E13)*Paramètres!$C$13,0) -> 8582 | U13: =ROUND(MAX(0,N($E13)-(Q13-R13)-M13)*Paramètres!$C$12,0) -> 2530 | V13: =ROUND(N($E13)-M13-S13-U13,0) -> 250432
B14: 8 | C14: KABRE Ali | D14: 45677 | E14: ='Jan-fév-mars-avril-mai-juin'!E12 -> 286055 | F14: =MIN(ROUNDDOWN(N($E14)*Paramètres!$C$16,0),Paramètres!$D$16) -> 57211 | G14: =MIN(ROUNDDOWN(N($E14)*Paramètres!$C$17,0),Paramètres!$D$17) -> 14302 | H14: =MIN(ROUNDDOWN(N($E14)*Paramètres!$C$18,0),Paramètres!$D$18) -> 14302 | I14: =N($E14)-(F14+G14+H14) -> 200240 | J14: 0 | K14: =IF(I14<Paramètres!$C$11,"Cadre inférieur","Cadre supérieur") -> Cadre supérieur | L14: =MIN(F14,MIN(N($E14)*Paramètres!$C$16,Paramètres!$D$16))+MIN(G14,MIN(N($E14)*Paramètres!$C$17,Paramètres!$D$17))+MIN(H14,MIN(N($E14)*Paramètres!$C$18,Paramètres!$D$18)) -> 85815 | M14: =MIN(N($E14),Paramètres!$C$7)*Paramètres!$C$6 -> 15733.025 | N14: =MIN(M14,I14*Paramètres!$C$8) -> 15733.025 | O14: =I14*IF(K14="Cadre supérieur",Paramètres!$C$10,Paramètres!$C$9) -> 40048 | P14: =MAX(0,ROUNDDOWN(N($E14)-L14-N14-O14,-2)) -> 144400 | Q14: =SUMPRODUCT((P14>Paramètres!$B$21:$B$27)*(P14-Paramètres!$B$21:$B$27)*Paramètres!$E$21:$E$27) -> 17359.6 | R14: =Q14*INDEX(Paramètres!$C$31:$C$38,MIN(MAX(INT(N(J14)),0),7)+1) -> 0 | S14: =ROUND(Q14-R14,0) -> 17360 | T14: =ROUND(N($E14)*Paramètres!$C$13,0) -> 8582 | U14: =ROUND(MAX(0,N($E14)-(Q14-R14)-M14)*Paramètres!$C$12,0) -> 2530 | V14: =ROUND(N($E14)-M14-S14-U14,0) -> 250432
B15: 9 | C15: KABRE Esther | D15: 46092 | E15: ='Jan-fév-mars-avril-mai-juin'!E13 -> 0 | F15: =MIN(ROUNDDOWN(N($E15)*Paramètres!$C$16,0),Paramètres!$D$16) -> 0 | G15: =MIN(ROUNDDOWN(N($E15)*Paramètres!$C$17,0),Paramètres!$D$17) -> 0 | H15: =MIN(ROUNDDOWN(N($E15)*Paramètres!$C$18,0),Paramètres!$D$18) -> 0 | I15: =N($E15)-(F15+G15+H15) -> 0 | J15: 0 | K15: =IF(I15<Paramètres!$C$11,"Cadre inférieur","Cadre supérieur") -> Cadre inférieur | L15: =MIN(F15,MIN(N($E15)*Paramètres!$C$16,Paramètres!$D$16))+MIN(G15,MIN(N($E15)*Paramètres!$C$17,Paramètres!$D$17))+MIN(H15,MIN(N($E15)*Paramètres!$C$18,Paramètres!$D$18)) -> 0 | M15: =MIN(N($E15),Paramètres!$C$7)*Paramètres!$C$6 -> 0 | N15: =MIN(M15,I15*Paramètres!$C$8) -> 0 | O15: =I15*IF(K15="Cadre supérieur",Paramètres!$C$10,Paramètres!$C$9) -> 0 | P15: =MAX(0,ROUNDDOWN(N($E15)-L15-N15-O15,-2)) -> 0 | Q15: =SUMPRODUCT((P15>Paramètres!$B$21:$B$27)*(P15-Paramètres!$B$21:$B$27)*Paramètres!$E$21:$E$27) -> 0 | R15: =Q15*INDEX(Paramètres!$C$31:$C$38,MIN(MAX(INT(N(J15)),0),7)+1) -> 0 | S15: =ROUND(Q15-R15,0) -> 0 | T15: =ROUND(N($E15)*Paramètres!$C$13,0) -> 0 | U15: =ROUND(MAX(0,N($E15)-(Q15-R15)-M15)*Paramètres!$C$12,0) -> 0 | V15: =ROUND(N($E15)-M15-S15-U15,0) -> 0
B16: Total par mois | E16: =SUM(E7:E15) -> 902790 | F16: =SUM(F7:F15) -> 180558 | G16: =SUM(G7:G15) -> 45138 | H16: =SUM(H7:H15) -> 45138 | I16: =SUM(I7:I15) -> 631956 | L16: =SUM(L7:L15) -> 270834 | M16: =SUM(M7:M15) -> 49653.45 | N16: =SUM(N7:N15) -> 49653.45 | O16: =SUM(O7:O15) -> 137965 | P16: =SUM(P7:P15) -> 444200 | Q16: =SUM(Q7:Q15) -> 47259.8 | R16: =SUM(R7:R15) -> 0 | S16: =SUM(S7:S15) -> 47260 | ... V16: =SUM(V7:V15) -> 797816
B17: CUMUL depuis janvier | E17: =E16 -> 902790 | S17: =S16 -> 47260 | T17: =T16 -> 27084 | U17: =U16 -> 8060 | V17: =V16 -> 797816
C19: Hypothèses du calcul IUTS (modifiables) :
C20: • 0 charge de famille pour tous — colonne « Nb charges » à corriger au besoin.
C21: • Catégorie : salaire de base < 150 000 → cadre inférieur (abattement 25 %) ; sinon cadre supérieur (abattement 20 %).
C22: • Rosalaire = 1 % × (brut − IUTS − CNSS) ; net à payer = brut − CNSS − IUTS − Rosalaire ; TPA = 3 % du brut, à la charge de l'employeur.
C23: • Brut ventilé au maximum exonéré : logement 20 % (≤ 75 000), transport 5 % (≤ 30 000), fonction 5 % (≤ 50 000) du brut ; le reste = salaire de base.
C24: • Taux, plafonds et barème : onglet « Paramètres ». IUTS net arrondi au franc.

Sheet Février
B4: ETAT DES SALAIRES KS SARL
B5: Période: | D5: FÉVRIER 2026 | F5: Ventilation simulée (max. exonéré) | J5: Hypothèses | L5: Calcul IUTS | T5: TPA, Rosalaire et net
B6: N° | C6: Nom&Prénom | D6: DATE D'ENTREE | E6: Brut Février | F6: Ind. Logement | G6: Ind. Transport | H6: Ind. Fonction | I6: Salaire de base | J6: Nb charges | K6: Catégorie | L6: Montant exonéré | M6: CNSS salarié 5,5 % | N6: Déduction retraite | O6: Abattement forfaitaire | P6: Base imposable (arr. 100) | Q6: IUTS brut | R6: Réduction charges | S6: IUTS NET | T6: TPA 3 % (patronale) | U6: Rosalaire 1 % | V6: SALAIRE NET À PAYER
B7: 1 | C7: OUEDRAOGO Abdoul Ganiyou | D7: 45881 | E7: ='Jan-fév-mars-avril-mai-juin'!F5 -> 225778 | F7: =MIN(ROUNDDOWN(N($E7)*Paramètres!$C$16,0),Paramètres!$D$16) -> 45155 | G7: =MIN(ROUNDDOWN(N($E7)*Paramètres!$C$17,0),Paramètres!$D$17) -> 11288 | H7: =MIN(ROUNDDOWN(N($E7)*Paramètres!$C$18,0),Paramètres!$D$18) -> 11288 | I7: =N($E7)-(F7+G7+H7) -> 158047 | J7: 0 | K7: =IF(I7<Paramètres!$C$11,"Cadre inférieur","Cadre supérieur") -> Cadre supérieur | L7: =MIN(F7,MIN(N($E7)*Paramètres!$C$16,Paramètres!$D$16))+MIN(G7,MIN(N($E7)*Paramètres!$C$17,Paramètres!$D$17))+MIN(H7,MIN(N($E7)*Paramètres!$C$18,Paramètres!$D$18)) -> 67731 | M7: =MIN(N($E7),Paramètres!$C$7)*Paramètres!$C$6 -> 12417.79 | N7: =MIN(M7,I7*Paramètres!$C$8) -> 12417.79 | O7: =I7*IF(K7="Cadre supérieur",Paramètres!$C$10,Paramètres!$C$9) -> 31609.4 | P7: =MAX(0,ROUNDDOWN(N($E7)-L7-N7-O7,-2)) -> 114000 | Q7: =SUMPRODUCT((P7>Paramètres!$B$21:$B$27)*(P7-Paramètres!$B$21:$B$27)*Paramètres!$E$21:$E$27) -> 11928 | R7: =Q7*INDEX(Paramètres!$C$31:$C$38,MIN(MAX(INT(N(J7)),0),7)+1) -> 0 | S7: =ROUND(Q7-R7,0) -> 11928 | T7: =ROUND(N($E7)*Paramètres!$C$13,0) -> 6773 | U7: =ROUND(MAX(0,N($E7)-(Q7-R7)-M7)*Paramètres!$C$12,0) -> 2014 | V7: =ROUND(N($E7)-M7-S7-U7,0) -> 199418
B8: 2 | C8: OUEDRAOGO Mohamed | D8: 45778 | E8: ='Jan-fév-mars-avril-mai-juin'!F6 -> 0 | F8: =MIN(ROUNDDOWN(N($E8)*Paramètres!$C$16,0),Paramètres!$D$16) -> 0 | G8: =MIN(ROUNDDOWN(N($E8)*Paramètres!$C$17,0),Paramètres!$D$17) -> 0 | H8: =MIN(ROUNDDOWN(N($E8)*Paramètres!$C$18,0),Paramètres!$D$18) -> 0 | I8: =N($E8)-(F8+G8+H8) -> 0 | J8: 0 | K8: =IF(I8<Paramètres!$C$11,"Cadre inférieur","Cadre supérieur") -> Cadre inférieur | L8: =MIN(F8,MIN(N($E8)*Paramètres!$C$16,Paramètres!$D$16))+MIN(G8,MIN(N($E8)*Paramètres!$C$17,Paramètres!$D$17))+MIN(H8,MIN(N($E8)*Paramètres!$C$18,Paramètres!$D$18)) -> 0 | M8: =MIN(N($E8),Paramètres!$C$7)*Paramètres!$C$6 -> 0 | N8: =MIN(M8,I8*Paramètres!$C$8) -> 0 | O8: =I8*IF(K8="Cadre supérieur",Paramètres!$C$10,Paramètres!$C$9) -> 0 | P8: =MAX(0,ROUNDDOWN(N($E8)-L8-N8-O8,-2)) -> 0 | Q8: =SUMPRODUCT((P8>Paramètres!$B$21:$B$27)*(P8-Paramètres!$B$21:$B$27)*Paramètres!$E$21:$E$27) -> 0 | R8: =Q8*INDEX(Paramètres!$C$31:$C$38,MIN(MAX(INT(N(J8)),0),7)+1) -> 0 | S8: =ROUND(Q8-R8,0) -> 0 | T8: =ROUND(N($E8)*Paramètres!$C$13,0) -> 0 | U8: =ROUND(MAX(0,N($E8)-(Q8-R8)-M8)*Paramètres!$C$12,0) -> 0 | V8: =ROUND(N($E8)-M8-S8-U8,0) -> 0
B9: 3 | C9: SAWADOGO Ibrahim | D9: 45912 | E9: ='Jan-fév-mars-avril-mai-juin'!F7 -> 0 | F9: =MIN(ROUNDDOWN(N($E9)*Paramètres!$C$16,0),Paramètres!$D$16) -> 0 | G9: =MIN(ROUNDDOWN(N($E9)*Paramètres!$C$17,0),Paramètres!$D$17) -> 0 | H9: =MIN(ROUNDDOWN(N($E9)*Paramètres!$C$18,0),Paramètres!$D$18) -> 0 | I9: =N($E9)-(F9+G9+H9) -> 0 | J9: 0 | K9: =IF(I9<Paramètres!$C$11,"Cadre inférieur","Cadre supérieur") -> Cadre inférieur | L9: =MIN(F9,MIN(N($E9)*Paramètres!$C$16,Paramètres!$D$16))+MIN(G9,MIN(N($E9)*Paramètres!$C$17,Paramètres!$D$17))+MIN(H9,MIN(N($E9)*Paramètres!$C$18,Paramètres!$D$18)) -> 0 | M9: =MIN(N($E9),Paramètres!$C$7)*Paramètres!$C$6 -> 0 | N9: =MIN(M9,I9*Paramètres!$C$8) -> 0 | O9: =I9*IF(K9="Cadre supérieur",Paramètres!$C$10,Paramètres!$C$9) -> 0 | P9: =MAX(0,ROUNDDOWN(N($E9)-L9-N9-O9,-2)) -> 0 | Q9: =SUMPRODUCT((P9>Paramètres!$B$21:$B$27)*(P9-Paramètres!$B$21:$B$27)*Paramètres!$E$21:$E$27) -> 0 | R9: =Q9*INDEX(Paramètres!$C$31:$C$38,MIN(MAX(INT(N(J9)),0),7)+1) -> 0 | S9: =ROUND(Q9-R9,0) -> 0 | T9: =ROUND(N($E9)*Paramètres!$C$13,0) -> 0 | U9: =ROUND(MAX(0,N($E9)-(Q9-R9)-M9)*Paramètres!$C$12,0) -> 0 | V9: =ROUND(N($E9)-M9-S9-U9,0) -> 0
B10: 4 | C10: SALO Arouna | D10: 45778 | E10: ='Jan-fév-mars-avril-mai-juin'!F8 -> 0 | F10: =MIN(ROUNDDOWN(N($E10)*Paramètres!$C$16,0),Paramètres!$D$16) -> 0 | G10: =MIN(ROUNDDOWN(N($E10)*Paramètres!$C$17,0),Paramètres!$D$17) -> 0 | H10: =MIN(ROUNDDOWN(N($E10)*Paramètres!$C$18,0),Paramètres!$D$18) -> 0 | I10: =N($E10)-(F10+G10+H10) -> 0 | J10: 0 | K10: =IF(I10<Paramètres!$C$11,"Cadre inférieur","Cadre supérieur") -> Cadre inférieur | L10: =MIN(F10,MIN(N($E10)*Paramètres!$C$16,Paramètres!$D$16))+MIN(G10,MIN(N($E10)*Paramètres!$C$17,Paramètres!$D$17))+MIN(H10,MIN(N($E10)*Paramètres!$C$18,Paramètres!$D$18)) -> 0 | M10: =MIN(N($E10),Paramètres!$C$7)*Paramètres!$C$6 -> 0 | N10: =MIN(M10,I10*Paramètres!$C$8) -> 0 | O10: =I10*IF(K10="Cadre supérieur",Paramètres!$C$10,Paramètres!$C$9) -> 0 | P10: =MAX(0,ROUNDDOWN(N($E10)-L10-N10-O10,-2)) -> 0 | Q10: =SUMPRODUCT((P10>Paramètres!$B$21:$B$27)*(P10-Paramètres!$B$21:$B$27)*Paramètres!$E$21:$E$27) -> 0 | R10: =Q10*INDEX(Paramètres!$C$31:$C$38,MIN(MAX(INT(N(J10)),0),7)+1) -> 0 | S10: =ROUND(Q10-R10,0) -> 0 | T10: =ROUND(N($E10)*Paramètres!$C$13,0) -> 0 | U10: =ROUND(MAX(0,N($E10)-(Q10-R10)-M10)*Paramètres!$C$12,0) -> 0 | V10: =ROUND(N($E10)-M10-S10-U10,0) -> 0
B11: 5 | C11: ILBOUDO Jean Marie | D11: 46000 | E11: ='Jan-fév-mars-avril-mai-juin'!F9 -> 0 | F11: =MIN(ROUNDDOWN(N($E11)*Paramètres!$C$16,0),Paramètres!$D$16) -> 0 | G11: =MIN(ROUNDDOWN(N($E11)*Paramètres!$C$17,0),Paramètres!$D$17) -> 0 | H11: =MIN(ROUNDDOWN(N($E11)*Paramètres!$C$18,0),Paramètres!$D$18) -> 0 | I11: =N($E11)-(F11+G11+H11) -> 0 | J11: 0 | K11: =IF(I11<Paramètres!$C$11,"Cadre inférieur","Cadre supérieur") -> Cadre inférieur | L11: =MIN(F11,MIN(N($E11)*Paramètres!$C$16,Paramètres!$D$16))+MIN(G11,MIN(N($E11)*Paramètres!$C$17,Paramètres!$D$17))+MIN(H11,MIN(N($E11)*Paramètres!$C$18,Paramètres!$D$18)) -> 0 | M11: =MIN(N($E11),Paramètres!$C$7)*Paramètres!$C$6 -> 0 | N11: =MIN(M11,I11*Paramètres!$C$8) -> 0 | O11: =I11*IF(K11="Cadre supérieur",Paramètres!$C$10,Paramètres!$C$9) -> 0 | P11: =MAX(0,ROUNDDOWN(N($E11)-L11-N11-O11,-2)) -> 0 | Q11: =SUMPRODUCT((P11>Paramètres!$B$21:$B$27)*(P11-Paramètres!$B$21:$B$27)*Paramètres!$E$21:$E$27) -> 0 | R11: =Q11*INDEX(Paramètres!$C$31:$C$38,MIN(MAX(INT(N(J11)),0),7)+1) -> 0 | S11: =ROUND(Q11-R11,0) -> 0 | T11: =ROUND(N($E11)*Paramètres!$C$13,0) -> 0 | U11: =ROUND(MAX(0,N($E11)-(Q11-R11)-M11)*Paramètres!$C$12,0) -> 0 | V11: =ROUND(N($E11)-M11-S11-U11,0) -> 0
B12: 6 | C12: KOMPAORE Anicet | D12: 45778 | E12: ='Jan-fév-mars-avril-mai-juin'!F10 -> 225778 | F12: =MIN(ROUNDDOWN(N($E12)*Paramètres!$C$16,0),Paramètres!$D$16) -> 45155 | G12: =MIN(ROUNDDOWN(N($E12)*Paramètres!$C$17,0),Paramètres!$D$17) -> 11288 | H12: =MIN(ROUNDDOWN(N($E12)*Paramètres!$C$18,0),Paramètres!$D$18) -> 11288 | I12: =N($E12)-(F12+G12+H12) -> 158047 | J12: 0 | K12: =IF(I12<Paramètres!$C$11,"Cadre inférieur","Cadre supérieur") -> Cadre supérieur | L12: =MIN(F12,MIN(N($E12)*Paramètres!$C$16,Paramètres!$D$16))+MIN(G12,MIN(N($E12)*Paramètres!$C$17,Paramètres!$D$17))+MIN(H12,MIN(N($E12)*Paramètres!$C$18,Paramètres!$D$18)) -> 67731 | M12: =MIN(N($E12),Paramètres!$C$7)*Paramètres!$C$6 -> 12417.79 | N12: =MIN(M12,I12*Paramètres!$C$8) -> 12417.79 | O12: =I12*IF(K12="Cadre supérieur",Paramètres!$C$10,Paramètres!$C$9) -> 31609.4 | P12: =MAX(0,ROUNDDOWN(N($E12)-L12-N12-O12,-2)) -> 114000 | Q12: =SUMPRODUCT((P12>Paramètres!$B$21:$B$27)*(P12-Paramètres!$B$21:$B$27)*Paramètres!$E$21:$E$27) -> 11928 | R12: =Q12*INDEX(Paramètres!$C$31:$C$38,MIN(MAX(INT(N(J12)),0),7)+1) -> 0 | S12: =ROUND(Q12-R12,0) -> 11928 | T12: =ROUND(N($E12)*Paramètres!$C$13,0) -> 6773 | U12: =ROUND(MAX(0,N($E12)-(Q12-R12)-M12)*Paramètres!$C$12,0) -> 2014 | V12: =ROUND(N($E12)-M12-S12-U12,0) -> 199418
B13: 7 | C13: BASSOLE Ines | D13: 45677 | E13: ='Jan-fév-mars-avril-mai-juin'!F11 -> 286055 | F13: =MIN(ROUNDDOWN(N($E13)*Paramètres!$C$16,0),Paramètres!$D$16) -> 57211 | G13: =MIN(ROUNDDOWN(N($E13)*Paramètres!$C$17,0),Paramètres!$D$17) -> 14302 | H13: =MIN(ROUNDDOWN(N($E13)*Paramètres!$C$18,0),Paramètres!$D$18) -> 14302 | I13: =N($E13)-(F13+G13+H13) -> 200240 | J13: 0 | K13: =IF(I13<Paramètres!$C$11,"Cadre inférieur","Cadre supérieur") -> Cadre supérieur | L13: =MIN(F13,MIN(N($E13)*Paramètres!$C$16,Paramètres!$D$16))+MIN(G13,MIN(N($E13)*Paramètres!$C$17,Paramètres!$D$17))+MIN(H13,MIN(N($E13)*Paramètres!$C$18,Paramètres!$D$18)) -> 85815 | M13: =MIN(N($E13),Paramètres!$C$7)*Paramètres!$C$6 -> 15733.025 | N13: =MIN(M13,I13*Paramètres!$C$8) -> 15733.025 | O13: =I13*IF(K13="Cadre supérieur",Paramètres!$C$10,Paramètres!$C$9) -> 40048 | P13: =MAX(0,ROUNDDOWN(N($E13)-L13-N13-O13,-2)) -> 144400 | Q13: =SUMPRODUCT((P13>Paramètres!$B$21:$B$27)*(P13-Paramètres!$B$21:$B$27)*Paramètres!$E$21:$E$27) -> 17359.6 | R13: =Q13*INDEX(Paramètres!$C$31:$C$38,MIN(MAX(INT(N(J13)),0),7)+1) -> 0 | S13: =ROUND(Q13-R13,0) -> 17360 | T13: =ROUND(N($E13)*Paramètres!$C$13,0) -> 8582 | U13: =ROUND(MAX(0,N($E13)-(Q13-R13)-M13)*Paramètres!$C$12,0) -> 2530 | V13: =ROUND(N($E13)-M13-S13-U13,0) -> 250432
B14: 8 | C14: KABRE Ali | D14: 45677 | E14: ='Jan-fév-mars-avril-mai-juin'!F12 -> 286055 | F14: =MIN(ROUNDDOWN(N($E14)*Paramètres!$C$16,0),Paramètres!$D$16) -> 57211 | G14: =MIN(ROUNDDOWN(N($E14)*Paramètres!$C$17,0),Paramètres!$D$17) -> 14302 | H14: =MIN(ROUNDDOWN(N($E14)*Paramètres!$C$18,0),Paramètres!$D$18) -> 14302 | I14: =N($E14)-(F14+G14+H14) -> 200240 | J14: 0 | K14: =IF(I14<Paramètres!$C$11,"Cadre inférieur","Cadre supérieur") -> Cadre supérieur | L14: =MIN(F14,MIN(N($E14)*Paramètres!$C$16,Paramètres!$D$16))+MIN(G14,MIN(N($E14)*Paramètres!$C$17,Paramètres!$D$17))+MIN(H14,MIN(N($E14)*Paramètres!$C$18,Paramètres!$D$18)) -> 85815 | M14: =MIN(N($E14),Paramètres!$C$7)*Paramètres!$C$6 -> 15733.025 | N14: =MIN(M14,I14*Paramètres!$C$8) -> 15733.025 | O14: =I14*IF(K14="Cadre supérieur",Paramètres!$C$10,Paramètres!$C$9) -> 40048 | P14: =MAX(0,ROUNDDOWN(N($E14)-L14-N14-O14,-2)) -> 144400 | Q14: =SUMPRODUCT((P14>Paramètres!$B$21:$B$27)*(P14-Paramètres!$B$21:$B$27)*Paramètres!$E$21:$E$27) -> 17359.6 | R14: =Q14*INDEX(Paramètres!$C$31:$C$38,MIN(MAX(INT(N(J14)),0),7)+1) -> 0 | S14: =ROUND(Q14-R14,0) -> 17360 | T14: =ROUND(N($E14)*Paramètres!$C$13,0) -> 8582 | U14: =ROUND(MAX(0,N($E14)-(Q14-R14)-M14)*Paramètres!$C$12,0) -> 2530 | V14: =ROUND(N($E14)-M14-S14-U14,0) -> 250432
B15: 9 | C15: KABRE Esther | D15: 46092 | E15: ='Jan-fév-mars-avril-mai-juin'!F13 -> 0 | F15: =MIN(ROUNDDOWN(N($E15)*Paramètres!$C$16,0),Paramètres!$D$16) -> 0 | G15: =MIN(ROUNDDOWN(N($E15)*Paramètres!$C$17,0),Paramètres!$D$17) -> 0 | H15: =MIN(ROUNDDOWN(N($E15)*Paramètres!$C$18,0),Paramètres!$D$18) -> 0 | I15: =N($E15)-(F15+G15+H15) -> 0 | J15: 0 | K15: =IF(I15<Paramètres!$C$11,"Cadre inférieur","Cadre supérieur") -> Cadre inférieur | L15: =MIN(F15,MIN(N($E15)*Paramètres!$C$16,Paramètres!$D$16))+MIN(G15,MIN(N($E15)*Paramètres!$C$17,Paramètres!$D$17))+MIN(H15,MIN(N($E15)*Paramètres!$C$18,Paramètres!$D$18)) -> 0 | M15: =MIN(N($E15),Paramètres!$C$7)*Paramètres!$C$6 -> 0 | N15: =MIN(M15,I15*Paramètres!$C$8) -> 0 | O15: =I15*IF(K15="Cadre supérieur",Paramètres!$C$10,Paramètres!$C$9) -> 0 | P15: =MAX(0,ROUNDDOWN(N($E15)-L15-N15-O15,-2)) -> 0 | Q15: =SUMPRODUCT((P15>Paramètres!$B$21:$B$27)*(P15-Paramètres!$B$21:$B$27)*Paramètres!$E$21:$E$27) -> 0 | R15: =Q15*INDEX(Paramètres!$C$31:$C$38,MIN(MAX(INT(N(J15)),0),7)+1) -> 0 | S15: =ROUND(Q15-R15,0) -> 0 | T15: =ROUND(N($E15)*Paramètres!$C$13,0) -> 0 | U15: =ROUND(MAX(0,N($E15)-(Q15-R15)-M15)*Paramètres!$C$12,0) -> 0 | V15: =ROUND(N($E15)-M15-S15-U15,0) -> 0
B16: Total par mois | E16: =SUM(E7:E15) -> 1023666 | F16: =SUM(F7:F15) -> 204732 | G16: =SUM(G7:G15) -> 51180 | H16: =SUM(H7:H15) -> 51180 | I16: =SUM(I7:I15) -> 716574 | L16: =SUM(L7:L15) -> 307092 | M16: =SUM(M7:M15) -> 56301.63 | N16: =SUM(N7:N15) -> 56301.63 | O16: =SUM(O7:O15) -> 143314.8 | P16: =SUM(P7:P15) -> 516800 | Q16: =SUM(Q7:Q15) -> 58575.2 | R16: =SUM(R7:R15) -> 0 | S16: =SUM(S7:S15) -> 58576 | ... V16: =SUM(V7:V15) -> 899700
B17: CUMUL depuis janvier | E17: =Janvier!E17+E16 -> 1926456 | S17: =Janvier!S17+S16 -> 105836 | T17: =Janvier!T17+T16 -> 57794 | U17: =Janvier!U17+U16 -> 17148 | V17: =Janvier!V17+V16 -> 1697516
C19: Hypothèses du calcul IUTS (modifiables) :
C20: • 0 charge de famille pour tous — colonne « Nb charges » à corriger au besoin.
C21: • Catégorie : salaire de base < 150 000 → cadre inférieur (abattement 25 %) ; sinon cadre supérieur (abattement 20 %).
C22: • Rosalaire = 1 % × (brut − IUTS − CNSS) ; net à payer = brut − CNSS − IUTS − Rosalaire ; TPA = 3 % du brut, à la charge de l'employeur.
C23: • Brut ventilé au maximum exonéré : logement 20 % (≤ 75 000), transport 5 % (≤ 30 000), fonction 5 % (≤ 50 000) du brut ; le reste = salaire de base.
C24: • Taux, plafonds et barème : onglet « Paramètres ». IUTS net arrondi au franc.

Sheet Mars
B4: ETAT DES SALAIRES KS SARL
B5: Période: | D5: MARS 2026 | F5: Ventilation simulée (max. exonéré) | J5: Hypothèses | L5: Calcul IUTS | T5: TPA, Rosalaire et net
B6: N° | C6: Nom&Prénom | D6: DATE D'ENTREE | E6: Brut Mars | F6: Ind. Logement | G6: Ind. Transport | H6: Ind. Fonction | I6: Salaire de base | J6: Nb charges | K6: Catégorie | L6: Montant exonéré | M6: CNSS salarié 5,5 % | N6: Déduction retraite | O6: Abattement forfaitaire | P6: Base imposable (arr. 100) | Q6: IUTS brut | R6: Réduction charges | S6: IUTS NET | T6: TPA 3 % (patronale) | U6: Rosalaire 1 % | V6: SALAIRE NET À PAYER
B7: 1 | C7: OUEDRAOGO Abdoul Ganiyou | D7: 45881 | E7: ='Jan-fév-mars-avril-mai-juin'!G5 -> 225778 | F7: =MIN(ROUNDDOWN(N($E7)*Paramètres!$C$16,0),Paramètres!$D$16) -> 45155 | G7: =MIN(ROUNDDOWN(N($E7)*Paramètres!$C$17,0),Paramètres!$D$17) -> 11288 | H7: =MIN(ROUNDDOWN(N($E7)*Paramètres!$C$18,0),Paramètres!$D$18) -> 11288 | I7: =N($E7)-(F7+G7+H7) -> 158047 | J7: 0 | K7: =IF(I7<Paramètres!$C$11,"Cadre inférieur","Cadre supérieur") -> Cadre supérieur | L7: =MIN(F7,MIN(N($E7)*Paramètres!$C$16,Paramètres!$D$16))+MIN(G7,MIN(N($E7)*Paramètres!$C$17,Paramètres!$D$17))+MIN(H7,MIN(N($E7)*Paramètres!$C$18,Paramètres!$D$18)) -> 67731 | M7: =MIN(N($E7),Paramètres!$C$7)*Paramètres!$C$6 -> 12417.79 | N7: =MIN(M7,I7*Paramètres!$C$8) -> 12417.79 | O7: =I7*IF(K7="Cadre supérieur",Paramètres!$C$10,Paramètres!$C$9) -> 31609.4 | P7: =MAX(0,ROUNDDOWN(N($E7)-L7-N7-O7,-2)) -> 114000 | Q7: =SUMPRODUCT((P7>Paramètres!$B$21:$B$27)*(P7-Paramètres!$B$21:$B$27)*Paramètres!$E$21:$E$27) -> 11928 | R7: =Q7*INDEX(Paramètres!$C$31:$C$38,MIN(MAX(INT(N(J7)),0),7)+1) -> 0 | S7: =ROUND(Q7-R7,0) -> 11928 | T7: =ROUND(N($E7)*Paramètres!$C$13,0) -> 6773 | U7: =ROUND(MAX(0,N($E7)-(Q7-R7)-M7)*Paramètres!$C$12,0) -> 2014 | V7: =ROUND(N($E7)-M7-S7-U7,0) -> 199418
B8: 2 | C8: OUEDRAOGO Mohamed | D8: 45778 | E8: ='Jan-fév-mars-avril-mai-juin'!G6 -> 213563 | F8: =MIN(ROUNDDOWN(N($E8)*Paramètres!$C$16,0),Paramètres!$D$16) -> 42712 | G8: =MIN(ROUNDDOWN(N($E8)*Paramètres!$C$17,0),Paramètres!$D$17) -> 10678 | H8: =MIN(ROUNDDOWN(N($E8)*Paramètres!$C$18,0),Paramètres!$D$18) -> 10678 | I8: =N($E8)-(F8+G8+H8) -> 149495 | J8: 0 | K8: =IF(I8<Paramètres!$C$11,"Cadre inférieur","Cadre supérieur") -> Cadre inférieur | L8: =MIN(F8,MIN(N($E8)*Paramètres!$C$16,Paramètres!$D$16))+MIN(G8,MIN(N($E8)*Paramètres!$C$17,Paramètres!$D$17))+MIN(H8,MIN(N($E8)*Paramètres!$C$18,Paramètres!$D$18)) -> 64068 | M8: =MIN(N($E8),Paramètres!$C$7)*Paramètres!$C$6 -> 11745.965 | N8: =MIN(M8,I8*Paramètres!$C$8) -> 11745.965 | O8: =I8*IF(K8="Cadre supérieur",Paramètres!$C$10,Paramètres!$C$9) -> 37373.75 | P8: =MAX(0,ROUNDDOWN(N($E8)-L8-N8-O8,-2)) -> 100300 | Q8: =SUMPRODUCT((P8>Paramètres!$B$21:$B$27)*(P8-Paramètres!$B$21:$B$27)*Paramètres!$E$21:$E$27) -> 9777.1 | R8: =Q8*INDEX(Paramètres!$C$31:$C$38,MIN(MAX(INT(N(J8)),0),7)+1) -> 0 | S8: =ROUND(Q8-R8,0) -> 9777 | T8: =ROUND(N($E8)*Paramètres!$C$13,0) -> 6407 | U8: =ROUND(MAX(0,N($E8)-(Q8-R8)-M8)*Paramètres!$C$12,0) -> 1920 | V8: =ROUND(N($E8)-M8-S8-U8,0) -> 190120
B9: 3 | C9: SAWADOGO Ibrahim | D9: 45912 | E9: ='Jan-fév-mars-avril-mai-juin'!G7 -> 213566 | F9: =MIN(ROUNDDOWN(N($E9)*Paramètres!$C$16,0),Paramètres!$D$16) -> 42713 | G9: =MIN(ROUNDDOWN(N($E9)*Paramètres!$C$17,0),Paramètres!$D$17) -> 10678 | H9: =MIN(ROUNDDOWN(N($E9)*Paramètres!$C$18,0),Paramètres!$D$18) -> 10678 | I9: =N($E9)-(F9+G9+H9) -> 149497 | J9: 0 | K9: =IF(I9<Paramètres!$C$11,"Cadre inférieur","Cadre supérieur") -> Cadre inférieur | L9: =MIN(F9,MIN(N($E9)*Paramètres!$C$16,Paramètres!$D$16))+MIN(G9,MIN(N($E9)*Paramètres!$C$17,Paramètres!$D$17))+MIN(H9,MIN(N($E9)*Paramètres!$C$18,Paramètres!$D$18)) -> 64069 | M9: =MIN(N($E9),Paramètres!$C$7)*Paramètres!$C$6 -> 11746.13 | N9: =MIN(M9,I9*Paramètres!$C$8) -> 11746.13 | O9: =I9*IF(K9="Cadre supérieur",Paramètres!$C$10,Paramètres!$C$9) -> 37374.25 | P9: =MAX(0,ROUNDDOWN(N($E9)-L9-N9-O9,-2)) -> 100300 | Q9: =SUMPRODUCT((P9>Paramètres!$B$21:$B$27)*(P9-Paramètres!$B$21:$B$27)*Paramètres!$E$21:$E$27) -> 9777.1 | R9: =Q9*INDEX(Paramètres!$C$31:$C$38,MIN(MAX(INT(N(J9)),0),7)+1) -> 0 | S9: =ROUND(Q9-R9,0) -> 9777 | T9: =ROUND(N($E9)*Paramètres!$C$13,0) -> 6407 | U9: =ROUND(MAX(0,N($E9)-(Q9-R9)-M9)*Paramètres!$C$12,0) -> 1920 | V9: =ROUND(N($E9)-M9-S9-U9,0) -> 190123
B10: 4 | C10: SALO Arouna | D10: 45778 | E10: ='Jan-fév-mars-avril-mai-juin'!G8 -> 0 | F10: =MIN(ROUNDDOWN(N($E10)*Paramètres!$C$16,0),Paramètres!$D$16) -> 0 | G10: =MIN(ROUNDDOWN(N($E10)*Paramètres!$C$17,0),Paramètres!$D$17) -> 0 | H10: =MIN(ROUNDDOWN(N($E10)*Paramètres!$C$18,0),Paramètres!$D$18) -> 0 | I10: =N($E10)-(F10+G10+H10) -> 0 | J10: 0 | K10: =IF(I10<Paramètres!$C$11,"Cadre inférieur","Cadre supérieur") -> Cadre inférieur | L10: =MIN(F10,MIN(N($E10)*Paramètres!$C$16,Paramètres!$D$16))+MIN(G10,MIN(N($E10)*Paramètres!$C$17,Paramètres!$D$17))+MIN(H10,MIN(N($E10)*Paramètres!$C$18,Paramètres!$D$18)) -> 0 | M10: =MIN(N($E10),Paramètres!$C$7)*Paramètres!$C$6 -> 0 | N10: =MIN(M10,I10*Paramètres!$C$8) -> 0 | O10: =I10*IF(K10="Cadre supérieur",Paramètres!$C$10,Paramètres!$C$9) -> 0 | P10: =MAX(0,ROUNDDOWN(N($E10)-L10-N10-O10,-2)) -> 0 | Q10: =SUMPRODUCT((P10>Paramètres!$B$21:$B$27)*(P10-Paramètres!$B$21:$B$27)*Paramètres!$E$21:$E$27) -> 0 | R10: =Q10*INDEX(Paramètres!$C$31:$C$38,MIN(MAX(INT(N(J10)),0),7)+1) -> 0 | S10: =ROUND(Q10-R10,0) -> 0 | T10: =ROUND(N($E10)*Paramètres!$C$13,0) -> 0 | U10: =ROUND(MAX(0,N($E10)-(Q10-R10)-M10)*Paramètres!$C$12,0) -> 0 | V10: =ROUND(N($E10)-M10-S10-U10,0) -> 0
B11: 5 | C11: ILBOUDO Jean Marie | D11: 46000 | E11: ='Jan-fév-mars-avril-mai-juin'!G9 -> 0 | F11: =MIN(ROUNDDOWN(N($E11)*Paramètres!$C$16,0),Paramètres!$D$16) -> 0 | G11: =MIN(ROUNDDOWN(N($E11)*Paramètres!$C$17,0),Paramètres!$D$17) -> 0 | H11: =MIN(ROUNDDOWN(N($E11)*Paramètres!$C$18,0),Paramètres!$D$18) -> 0 | I11: =N($E11)-(F11+G11+H11) -> 0 | J11: 0 | K11: =IF(I11<Paramètres!$C$11,"Cadre inférieur","Cadre supérieur") -> Cadre inférieur | L11: =MIN(F11,MIN(N($E11)*Paramètres!$C$16,Paramètres!$D$16))+MIN(G11,MIN(N($E11)*Paramètres!$C$17,Paramètres!$D$17))+MIN(H11,MIN(N($E11)*Paramètres!$C$18,Paramètres!$D$18)) -> 0 | M11: =MIN(N($E11),Paramètres!$C$7)*Paramètres!$C$6 -> 0 | N11: =MIN(M11,I11*Paramètres!$C$8) -> 0 | O11: =I11*IF(K11="Cadre supérieur",Paramètres!$C$10,Paramètres!$C$9) -> 0 | P11: =MAX(0,ROUNDDOWN(N($E11)-L11-N11-O11,-2)) -> 0 | Q11: =SUMPRODUCT((P11>Paramètres!$B$21:$B$27)*(P11-Paramètres!$B$21:$B$27)*Paramètres!$E$21:$E$27) -> 0 | R11: =Q11*INDEX(Paramètres!$C$31:$C$38,MIN(MAX(INT(N(J11)),0),7)+1) -> 0 | S11: =ROUND(Q11-R11,0) -> 0 | T11: =ROUND(N($E11)*Paramètres!$C$13,0) -> 0 | U11: =ROUND(MAX(0,N($E11)-(Q11-R11)-M11)*Paramètres!$C$12,0) -> 0 | V11: =ROUND(N($E11)-M11-S11-U11,0) -> 0
B12: 6 | C12: KOMPAORE Anicet | D12: 45778 | E12: ='Jan-fév-mars-avril-mai-juin'!G10 -> 225778 | F12: =MIN(ROUNDDOWN(N($E12)*Paramètres!$C$16,0),Paramètres!$D$16) -> 45155 | G12: =MIN(ROUNDDOWN(N($E12)*Paramètres!$C$17,0),Paramètres!$D$17) -> 11288 | H12: =MIN(ROUNDDOWN(N($E12)*Paramètres!$C$18,0),Paramètres!$D$18) -> 11288 | I12: =N($E12)-(F12+G12+H12) -> 158047 | J12: 0 | K12: =IF(I12<Paramètres!$C$11,"Cadre inférieur","Cadre supérieur") -> Cadre supérieur | L12: =MIN(F12,MIN(N($E12)*Paramètres!$C$16,Paramètres!$D$16))+MIN(G12,MIN(N($E12)*Paramètres!$C$17,Paramètres!$D$17))+MIN(H12,MIN(N($E12)*Paramètres!$C$18,Paramètres!$D$18)) -> 67731 | M12: =MIN(N($E12),Paramètres!$C$7)*Paramètres!$C$6 -> 12417.79 | N12: =MIN(M12,I12*Paramètres!$C$8) -> 12417.79 | O12: =I12*IF(K12="Cadre supérieur",Paramètres!$C$10,Paramètres!$C$9) -> 31609.4 | P12: =MAX(0,ROUNDDOWN(N($E12)-L12-N12-O12,-2)) -> 114000 | Q12: =SUMPRODUCT((P12>Paramètres!$B$21:$B$27)*(P12-Paramètres!$B$21:$B$27)*Paramètres!$E$21:$E$27) -> 11928 | R12: =Q12*INDEX(Paramètres!$C$31:$C$38,MIN(MAX(INT(N(J12)),0),7)+1) -> 0 | S12: =ROUND(Q12-R12,0) -> 11928 | T12: =ROUND(N($E12)*Paramètres!$C$13,0) -> 6773 | U12: =ROUND(MAX(0,N($E12)-(Q12-R12)-M12)*Paramètres!$C$12,0) -> 2014 | V12: =ROUND(N($E12)-M12-S12-U12,0) -> 199418
B13: 7 | C13: BASSOLE Ines | D13: 45677 | E13: ='Jan-fév-mars-avril-mai-juin'!G11 -> 286055 | F13: =MIN(ROUNDDOWN(N($E13)*Paramètres!$C$16,0),Paramètres!$D$16) -> 57211 | G13: =MIN(ROUNDDOWN(N($E13)*Paramètres!$C$17,0),Paramètres!$D$17) -> 14302 | H13: =MIN(ROUNDDOWN(N($E13)*Paramètres!$C$18,0),Paramètres!$D$18) -> 14302 | I13: =N($E13)-(F13+G13+H13) -> 200240 | J13: 0 | K13: =IF(I13<Paramètres!$C$11,"Cadre inférieur","Cadre supérieur") -> Cadre supérieur | L13: =MIN(F13,MIN(N($E13)*Paramètres!$C$16,Paramètres!$D$16))+MIN(G13,MIN(N($E13)*Paramètres!$C$17,Paramètres!$D$17))+MIN(H13,MIN(N($E13)*Paramètres!$C$18,Paramètres!$D$18)) -> 85815 | M13: =MIN(N($E13),Paramètres!$C$7)*Paramètres!$C$6 -> 15733.025 | N13: =MIN(M13,I13*Paramètres!$C$8) -> 15733.025 | O13: =I13*IF(K13="Cadre supérieur",Paramètres!$C$10,Paramètres!$C$9) -> 40048 | P13: =MAX(0,ROUNDDOWN(N($E13)-L13-N13-O13,-2)) -> 144400 | Q13: =SUMPRODUCT((P13>Paramètres!$B$21:$B$27)*(P13-Paramètres!$B$21:$B$27)*Paramètres!$E$21:$E$27) -> 17359.6 | R13: =Q13*INDEX(Paramètres!$C$31:$C$38,MIN(MAX(INT(N(J13)),0),7)+1) -> 0 | S13: =ROUND(Q13-R13,0) -> 17360 | T13: =ROUND(N($E13)*Paramètres!$C$13,0) -> 8582 | U13: =ROUND(MAX(0,N($E13)-(Q13-R13)-M13)*Paramètres!$C$12,0) -> 2530 | V13: =ROUND(N($E13)-M13-S13-U13,0) -> 250432
B14: 8 | C14: KABRE Ali | D14: 45677 | E14: ='Jan-fév-mars-avril-mai-juin'!G12 -> 286055 | F14: =MIN(ROUNDDOWN(N($E14)*Paramètres!$C$16,0),Paramètres!$D$16) -> 57211 | G14: =MIN(ROUNDDOWN(N($E14)*Paramètres!$C$17,0),Paramètres!$D$17) -> 14302 | H14: =MIN(ROUNDDOWN(N($E14)*Paramètres!$C$18,0),Paramètres!$D$18) -> 14302 | I14: =N($E14)-(F14+G14+H14) -> 200240 | J14: 0 | K14: =IF(I14<Paramètres!$C$11,"Cadre inférieur","Cadre supérieur") -> Cadre supérieur | L14: =MIN(F14,MIN(N($E14)*Paramètres!$C$16,Paramètres!$D$16))+MIN(G14,MIN(N($E14)*Paramètres!$C$17,Paramètres!$D$17))+MIN(H14,MIN(N($E14)*Paramètres!$C$18,Paramètres!$D$18)) -> 85815 | M14: =MIN(N($E14),Paramètres!$C$7)*Paramètres!$C$6 -> 15733.025 | N14: =MIN(M14,I14*Paramètres!$C$8) -> 15733.025 | O14: =I14*IF(K14="Cadre supérieur",Paramètres!$C$10,Paramètres!$C$9) -> 40048 | P14: =MAX(0,ROUNDDOWN(N($E14)-L14-N14-O14,-2)) -> 144400 | Q14: =SUMPRODUCT((P14>Paramètres!$B$21:$B$27)*(P14-Paramètres!$B$21:$B$27)*Paramètres!$E$21:$E$27) -> 17359.6 | R14: =Q14*INDEX(Paramètres!$C$31:$C$38,MIN(MAX(INT(N(J14)),0),7)+1) -> 0 | S14: =ROUND(Q14-R14,0) -> 17360 | T14: =ROUND(N($E14)*Paramètres!$C$13,0) -> 8582 | U14: =ROUND(MAX(0,N($E14)-(Q14-R14)-M14)*Paramètres!$C$12,0) -> 2530 | V14: =ROUND(N($E14)-M14-S14-U14,0) -> 250432
B15: 9 | C15: KABRE Esther | D15: 46092 | E15: ='Jan-fév-mars-avril-mai-juin'!G13 -> 135983 | F15: =MIN(ROUNDDOWN(N($E15)*Paramètres!$C$16,0),Paramètres!$D$16) -> 27196 | G15: =MIN(ROUNDDOWN(N($E15)*Paramètres!$C$17,0),Paramètres!$D$17) -> 6799 | H15: =MIN(ROUNDDOWN(N($E15)*Paramètres!$C$18,0),Paramètres!$D$18) -> 6799 | I15: =N($E15)-(F15+G15+H15) -> 95189 | J15: 0 | K15: =IF(I15<Paramètres!$C$11,"Cadre inférieur","Cadre supérieur") -> Cadre inférieur | L15: =MIN(F15,MIN(N($E15)*Paramètres!$C$16,Paramètres!$D$16))+MIN(G15,MIN(N($E15)*Paramètres!$C$17,Paramètres!$D$17))+MIN(H15,MIN(N($E15)*Paramètres!$C$18,Paramètres!$D$18)) -> 40794 | M15: =MIN(N($E15),Paramètres!$C$7)*Paramètres!$C$6 -> 7479.065 | N15: =MIN(M15,I15*Paramètres!$C$8) -> 7479.065 | O15: =I15*IF(K15="Cadre supérieur",Paramètres!$C$10,Paramètres!$C$9) -> 23797.25 | P15: =MAX(0,ROUNDDOWN(N($E15)-L15-N15-O15,-2)) -> 63900 | Q15: =SUMPRODUCT((P15>Paramètres!$B$21:$B$27)*(P15-Paramètres!$B$21:$B$27)*Paramètres!$E$21:$E$27) -> 4352.1 | R15: =Q15*INDEX(Paramètres!$C$31:$C$38,MIN(MAX(INT(N(J15)),0),7)+1) -> 0 | S15: =ROUND(Q15-R15,0) -> 4352 | T15: =ROUND(N($E15)*Paramètres!$C$13,0) -> 4079 | U15: =ROUND(MAX(0,N($E15)-(Q15-R15)-M15)*Paramètres!$C$12,0) -> 1242 | V15: =ROUND(N($E15)-M15-S15-U15,0) -> 122910
B16: Total par mois | E16: =SUM(E7:E15) -> 1586778 | F16: =SUM(F7:F15) -> 317353 | G16: =SUM(G7:G15) -> 79335 | H16: =SUM(H7:H15) -> 79335 | I16: =SUM(I7:I15) -> 1110755 | L16: =SUM(L7:L15) -> 476023 | M16: =SUM(M7:M15) -> 87272.79 | N16: =SUM(N7:N15) -> 87272.79 | O16: =SUM(O7:O15) -> 241860.05 | P16: =SUM(P7:P15) -> 781300 | Q16: =SUM(Q7:Q15) -> 82481.5 | R16: =SUM(R7:R15) -> 0 | S16: =SUM(S7:S15) -> 82482 | ... V16: =SUM(V7:V15) -> 1402853
B17: CUMUL depuis janvier | E17: =Février!E17+E16 -> 3513234 | S17: =Février!S17+S16 -> 188318 | T17: =Février!T17+T16 -> 105397 | U17: =Février!U17+U16 -> 31318 | V17: =Février!V17+V16 -> 3100369
C19: Hypothèses du calcul IUTS (modifiables) :
C20: • 0 charge de famille pour tous — colonne « Nb charges » à corriger au besoin.
C21: • Catégorie : salaire de base < 150 000 → cadre inférieur (abattement 25 %) ; sinon cadre supérieur (abattement 20 %).
C22: • Rosalaire = 1 % × (brut − IUTS − CNSS) ; net à payer = brut − CNSS − IUTS − Rosalaire ; TPA = 3 % du brut, à la charge de l'employeur.
C23: • Brut ventilé au maximum exonéré : logement 20 % (≤ 75 000), transport 5 % (≤ 30 000), fonction 5 % (≤ 50 000) du brut ; le reste = salaire de base.
C24: • Taux, plafonds et barème : onglet « Paramètres ». IUTS net arrondi au franc.

Sheet Avril
B4: ETAT DES SALAIRES KS SARL
B5: Période: | D5: AVRIL 2026 | F5: Ventilation simulée (max. exonéré) | J5: Hypothèses | L5: Calcul IUTS | T5: TPA, Rosalaire et net
B6: N° | C6: Nom&Prénom | D6: DATE D'ENTREE | E6: Brut Avril | F6: Ind. Logement | G6: Ind. Transport | H6: Ind. Fonction | I6: Salaire de base | J6: Nb charges | K6: Catégorie | L6: Montant exonéré | M6: CNSS salarié 5,5 % | N6: Déduction retraite | O6: Abattement forfaitaire | P6: Base imposable (arr. 100) | Q6: IUTS brut | R6: Réduction charges | S6: IUTS NET | T6: TPA 3 % (patronale) | U6: Rosalaire 1 % | V6: SALAIRE NET À PAYER
B7: 1 | C7: OUEDRAOGO Abdoul Ganiyou | D7: 45881 | E7: ='Jan-fév-mars-avril-mai-juin'!H5 -> 225778 | F7: =MIN(ROUNDDOWN(N($E7)*Paramètres!$C$16,0),Paramètres!$D$16) -> 45155 | G7: =MIN(ROUNDDOWN(N($E7)*Paramètres!$C$17,0),Paramètres!$D$17) -> 11288 | H7: =MIN(ROUNDDOWN(N($E7)*Paramètres!$C$18,0),Paramètres!$D$18) -> 11288 | I7: =N($E7)-(F7+G7+H7) -> 158047 | J7: 0 | K7: =IF(I7<Paramètres!$C$11,"Cadre inférieur","Cadre supérieur") -> Cadre supérieur | L7: =MIN(F7,MIN(N($E7)*Paramètres!$C$16,Paramètres!$D$16))+MIN(G7,MIN(N($E7)*Paramètres!$C$17,Paramètres!$D$17))+MIN(H7,MIN(N($E7)*Paramètres!$C$18,Paramètres!$D$18)) -> 67731 | M7: =MIN(N($E7),Paramètres!$C$7)*Paramètres!$C$6 -> 12417.79 | N7: =MIN(M7,I7*Paramètres!$C$8) -> 12417.79 | O7: =I7*IF(K7="Cadre supérieur",Paramètres!$C$10,Paramètres!$C$9) -> 31609.4 | P7: =MAX(0,ROUNDDOWN(N($E7)-L7-N7-O7,-2)) -> 114000 | Q7: =SUMPRODUCT((P7>Paramètres!$B$21:$B$27)*(P7-Paramètres!$B$21:$B$27)*Paramètres!$E$21:$E$27) -> 11928 | R7: =Q7*INDEX(Paramètres!$C$31:$C$38,MIN(MAX(INT(N(J7)),0),7)+1) -> 0 | S7: =ROUND(Q7-R7,0) -> 11928 | T7: =ROUND(N($E7)*Paramètres!$C$13,0) -> 6773 | U7: =ROUND(MAX(0,N($E7)-(Q7-R7)-M7)*Paramètres!$C$12,0) -> 2014 | V7: =ROUND(N($E7)-M7-S7-U7,0) -> 199418
B8: 2 | C8: OUEDRAOGO Mohamed | D8: 45778 | E8: ='Jan-fév-mars-avril-mai-juin'!H6 -> 213563 | F8: =MIN(ROUNDDOWN(N($E8)*Paramètres!$C$16,0),Paramètres!$D$16) -> 42712 | G8: =MIN(ROUNDDOWN(N($E8)*Paramètres!$C$17,0),Paramètres!$D$17) -> 10678 | H8: =MIN(ROUNDDOWN(N($E8)*Paramètres!$C$18,0),Paramètres!$D$18) -> 10678 | I8: =N($E8)-(F8+G8+H8) -> 149495 | J8: 0 | K8: =IF(I8<Paramètres!$C$11,"Cadre inférieur","Cadre supérieur") -> Cadre inférieur | L8: =MIN(F8,MIN(N($E8)*Paramètres!$C$16,Paramètres!$D$16))+MIN(G8,MIN(N($E8)*Paramètres!$C$17,Paramètres!$D$17))+MIN(H8,MIN(N($E8)*Paramètres!$C$18,Paramètres!$D$18)) -> 64068 | M8: =MIN(N($E8),Paramètres!$C$7)*Paramètres!$C$6 -> 11745.965 | N8: =MIN(M8,I8*Paramètres!$C$8) -> 11745.965 | O8: =I8*IF(K8="Cadre supérieur",Paramètres!$C$10,Paramètres!$C$9) -> 37373.75 | P8: =MAX(0,ROUNDDOWN(N($E8)-L8-N8-O8,-2)) -> 100300 | Q8: =SUMPRODUCT((P8>Paramètres!$B$21:$B$27)*(P8-Paramètres!$B$21:$B$27)*Paramètres!$E$21:$E$27) -> 9777.1 | R8: =Q8*INDEX(Paramètres!$C$31:$C$38,MIN(MAX(INT(N(J8)),0),7)+1) -> 0 | S8: =ROUND(Q8-R8,0) -> 9777 | T8: =ROUND(N($E8)*Paramètres!$C$13,0) -> 6407 | U8: =ROUND(MAX(0,N($E8)-(Q8-R8)-M8)*Paramètres!$C$12,0) -> 1920 | V8: =ROUND(N($E8)-M8-S8-U8,0) -> 190120
B9: 3 | C9: SAWADOGO Ibrahim | D9: 45912 | E9: ='Jan-fév-mars-avril-mai-juin'!H7 -> 213566 | F9: =MIN(ROUNDDOWN(N($E9)*Paramètres!$C$16,0),Paramètres!$D$16) -> 42713 | G9: =MIN(ROUNDDOWN(N($E9)*Paramètres!$C$17,0),Paramètres!$D$17) -> 10678 | H9: =MIN(ROUNDDOWN(N($E9)*Paramètres!$C$18,0),Paramètres!$D$18) -> 10678 | I9: =N($E9)-(F9+G9+H9) -> 149497 | J9: 0 | K9: =IF(I9<Paramètres!$C$11,"Cadre inférieur","Cadre supérieur") -> Cadre inférieur | L9: =MIN(F9,MIN(N($E9)*Paramètres!$C$16,Paramètres!$D$16))+MIN(G9,MIN(N($E9)*Paramètres!$C$17,Paramètres!$D$17))+MIN(H9,MIN(N($E9)*Paramètres!$C$18,Paramètres!$D$18)) -> 64069 | M9: =MIN(N($E9),Paramètres!$C$7)*Paramètres!$C$6 -> 11746.13 | N9: =MIN(M9,I9*Paramètres!$C$8) -> 11746.13 | O9: =I9*IF(K9="Cadre supérieur",Paramètres!$C$10,Paramètres!$C$9) -> 37374.25 | P9: =MAX(0,ROUNDDOWN(N($E9)-L9-N9-O9,-2)) -> 100300 | Q9: =SUMPRODUCT((P9>Paramètres!$B$21:$B$27)*(P9-Paramètres!$B$21:$B$27)*Paramètres!$E$21:$E$27) -> 9777.1 | R9: =Q9*INDEX(Paramètres!$C$31:$C$38,MIN(MAX(INT(N(J9)),0),7)+1) -> 0 | S9: =ROUND(Q9-R9,0) -> 9777 | T9: =ROUND(N($E9)*Paramètres!$C$13,0) -> 6407 | U9: =ROUND(MAX(0,N($E9)-(Q9-R9)-M9)*Paramètres!$C$12,0) -> 1920 | V9: =ROUND(N($E9)-M9-S9-U9,0) -> 190123
B10: 4 | C10: SALO Arouna | D10: 45778 | E10: ='Jan-fév-mars-avril-mai-juin'!H8 -> 213566 | F10: =MIN(ROUNDDOWN(N($E10)*Paramètres!$C$16,0),Paramètres!$D$16) -> 42713 | G10: =MIN(ROUNDDOWN(N($E10)*Paramètres!$C$17,0),Paramètres!$D$17) -> 10678 | H10: =MIN(ROUNDDOWN(N($E10)*Paramètres!$C$18,0),Paramètres!$D$18) -> 10678 | I10: =N($E10)-(F10+G10+H10) -> 149497 | J10: 0 | K10: =IF(I10<Paramètres!$C$11,"Cadre inférieur","Cadre supérieur") -> Cadre inférieur | L10: =MIN(F10,MIN(N($E10)*Paramètres!$C$16,Paramètres!$D$16))+MIN(G10,MIN(N($E10)*Paramètres!$C$17,Paramètres!$D$17))+MIN(H10,MIN(N($E10)*Paramètres!$C$18,Paramètres!$D$18)) -> 64069 | M10: =MIN(N($E10),Paramètres!$C$7)*Paramètres!$C$6 -> 11746.13 | N10: =MIN(M10,I10*Paramètres!$C$8) -> 11746.13 | O10: =I10*IF(K10="Cadre supérieur",Paramètres!$C$10,Paramètres!$C$9) -> 37374.25 | P10: =MAX(0,ROUNDDOWN(N($E10)-L10-N10-O10,-2)) -> 100300 | Q10: =SUMPRODUCT((P10>Paramètres!$B$21:$B$27)*(P10-Paramètres!$B$21:$B$27)*Paramètres!$E$21:$E$27) -> 9777.1 | R10: =Q10*INDEX(Paramètres!$C$31:$C$38,MIN(MAX(INT(N(J10)),0),7)+1) -> 0 | S10: =ROUND(Q10-R10,0) -> 9777 | T10: =ROUND(N($E10)*Paramètres!$C$13,0) -> 6407 | U10: =ROUND(MAX(0,N($E10)-(Q10-R10)-M10)*Paramètres!$C$12,0) -> 1920 | V10: =ROUND(N($E10)-M10-S10-U10,0) -> 190123
B11: 5 | C11: ILBOUDO Jean Marie | D11: 46000 | E11: ='Jan-fév-mars-avril-mai-juin'!H9 -> 177387 | F11: =MIN(ROUNDDOWN(N($E11)*Paramètres!$C$16,0),Paramètres!$D$16) -> 35477 | G11: =MIN(ROUNDDOWN(N($E11)*Paramètres!$C$17,0),Paramètres!$D$17) -> 8869 | H11: =MIN(ROUNDDOWN(N($E11)*Paramètres!$C$18,0),Paramètres!$D$18) -> 8869 | I11: =N($E11)-(F11+G11+H11) -> 124172 | J11: 0 | K11: =IF(I11<Paramètres!$C$11,"Cadre inférieur","Cadre supérieur") -> Cadre inférieur | L11: =MIN(F11,MIN(N($E11)*Paramètres!$C$16,Paramètres!$D$16))+MIN(G11,MIN(N($E11)*Paramètres!$C$17,Paramètres!$D$17))+MIN(H11,MIN(N($E11)*Paramètres!$C$18,Paramètres!$D$18)) -> 53215 | M11: =MIN(N($E11),Paramètres!$C$7)*Paramètres!$C$6 -> 9756.285 | N11: =MIN(M11,I11*Paramètres!$C$8) -> 9756.285 | O11: =I11*IF(K11="Cadre supérieur",Paramètres!$C$10,Paramètres!$C$9) -> 31043 | P11: =MAX(0,ROUNDDOWN(N($E11)-L11-N11-O11,-2)) -> 83300 | Q11: =SUMPRODUCT((P11>Paramètres!$B$21:$B$27)*(P11-Paramètres!$B$21:$B$27)*Paramètres!$E$21:$E$27) -> 7108.1 | R11: =Q11*INDEX(Paramètres!$C$31:$C$38,MIN(MAX(INT(N(J11)),0),7)+1) -> 0 | S11: =ROUND(Q11-R11,0) -> 7108 | T11: =ROUND(N($E11)*Paramètres!$C$13,0) -> 5322 | U11: =ROUND(MAX(0,N($E11)-(Q11-R11)-M11)*Paramètres!$C$12,0) -> 1605 | V11: =ROUND(N($E11)-M11-S11-U11,0) -> 158918
B12: 6 | C12: KOMPAORE Anicet | D12: 45778 | E12: ='Jan-fév-mars-avril-mai-juin'!H10 -> 225778 | F12: =MIN(ROUNDDOWN(N($E12)*Paramètres!$C$16,0),Paramètres!$D$16) -> 45155 | G12: =MIN(ROUNDDOWN(N($E12)*Paramètres!$C$17,0),Paramètres!$D$17) -> 11288 | H12: =MIN(ROUNDDOWN(N($E12)*Paramètres!$C$18,0),Paramètres!$D$18) -> 11288 | I12: =N($E12)-(F12+G12+H12) -> 158047 | J12: 0 | K12: =IF(I12<Paramètres!$C$11,"Cadre inférieur","Cadre supérieur") -> Cadre supérieur | L12: =MIN(F12,MIN(N($E12)*Paramètres!$C$16,Paramètres!$D$16))+MIN(G12,MIN(N($E12)*Paramètres!$C$17,Paramètres!$D$17))+MIN(H12,MIN(N($E12)*Paramètres!$C$18,Paramètres!$D$18)) -> 67731 | M12: =MIN(N($E12),Paramètres!$C$7)*Paramètres!$C$6 -> 12417.79 | N12: =MIN(M12,I12*Paramètres!$C$8) -> 12417.79 | O12: =I12*IF(K12="Cadre supérieur",Paramètres!$C$10,Paramètres!$C$9) -> 31609.4 | P12: =MAX(0,ROUNDDOWN(N($E12)-L12-N12-O12,-2)) -> 114000 | Q12: =SUMPRODUCT((P12>Paramètres!$B$21:$B$27)*(P12-Paramètres!$B$21:$B$27)*Paramètres!$E$21:$E$27) -> 11928 | R12: =Q12*INDEX(Paramètres!$C$31:$C$38,MIN(MAX(INT(N(J12)),0),7)+1) -> 0 | S12: =ROUND(Q12-R12,0) -> 11928 | T12: =ROUND(N($E12)*Paramètres!$C$13,0) -> 6773 | U12: =ROUND(MAX(0,N($E12)-(Q12-R12)-M12)*Paramètres!$C$12,0) -> 2014 | V12: =ROUND(N($E12)-M12-S12-U12,0) -> 199418
B13: 7 | C13: BASSOLE Ines | D13: 45677 | E13: ='Jan-fév-mars-avril-mai-juin'!H11 -> 286055 | F13: =MIN(ROUNDDOWN(N($E13)*Paramètres!$C$16,0),Paramètres!$D$16) -> 57211 | G13: =MIN(ROUNDDOWN(N($E13)*Paramètres!$C$17,0),Paramètres!$D$17) -> 14302 | H13: =MIN(ROUNDDOWN(N($E13)*Paramètres!$C$18,0),Paramètres!$D$18) -> 14302 | I13: =N($E13)-(F13+G13+H13) -> 200240 | J13: 0 | K13: =IF(I13<Paramètres!$C$11,"Cadre inférieur","Cadre supérieur") -> Cadre supérieur | L13: =MIN(F13,MIN(N($E13)*Paramètres!$C$16,Paramètres!$D$16))+MIN(G13,MIN(N($E13)*Paramètres!$C$17,Paramètres!$D$17))+MIN(H13,MIN(N($E13)*Paramètres!$C$18,Paramètres!$D$18)) -> 85815 | M13: =MIN(N($E13),Paramètres!$C$7)*Paramètres!$C$6 -> 15733.025 | N13: =MIN(M13,I13*Paramètres!$C$8) -> 15733.025 | O13: =I13*IF(K13="Cadre supérieur",Paramètres!$C$10,Paramètres!$C$9) -> 40048 | P13: =MAX(0,ROUNDDOWN(N($E13)-L13-N13-O13,-2)) -> 144400 | Q13: =SUMPRODUCT((P13>Paramètres!$B$21:$B$27)*(P13-Paramètres!$B$21:$B$27)*Paramètres!$E$21:$E$27) -> 17359.6 | R13: =Q13*INDEX(Paramètres!$C$31:$C$38,MIN(MAX(INT(N(J13)),0),7)+1) -> 0 | S13: =ROUND(Q13-R13,0) -> 17360 | T13: =ROUND(N($E13)*Paramètres!$C$13,0) -> 8582 | U13: =ROUND(MAX(0,N($E13)-(Q13-R13)-M13)*Paramètres!$C$12,0) -> 2530 | V13: =ROUND(N($E13)-M13-S13-U13,0) -> 250432
B14: 8 | C14: KABRE Ali | D14: 45677 | E14: ='Jan-fév-mars-avril-mai-juin'!H12 -> 286055 | F14: =MIN(ROUNDDOWN(N($E14)*Paramètres!$C$16,0),Paramètres!$D$16) -> 57211 | G14: =MIN(ROUNDDOWN(N($E14)*Paramètres!$C$17,0),Paramètres!$D$17) -> 14302 | H14: =MIN(ROUNDDOWN(N($E14)*Paramètres!$C$18,0),Paramètres!$D$18) -> 14302 | I14: =N($E14)-(F14+G14+H14) -> 200240 | J14: 0 | K14: =IF(I14<Paramètres!$C$11,"Cadre inférieur","Cadre supérieur") -> Cadre supérieur | L14: =MIN(F14,MIN(N($E14)*Paramètres!$C$16,Paramètres!$D$16))+MIN(G14,MIN(N($E14)*Paramètres!$C$17,Paramètres!$D$17))+MIN(H14,MIN(N($E14)*Paramètres!$C$18,Paramètres!$D$18)) -> 85815 | M14: =MIN(N($E14),Paramètres!$C$7)*Paramètres!$C$6 -> 15733.025 | N14: =MIN(M14,I14*Paramètres!$C$8) -> 15733.025 | O14: =I14*IF(K14="Cadre supérieur",Paramètres!$C$10,Paramètres!$C$9) -> 40048 | P14: =MAX(0,ROUNDDOWN(N($E14)-L14-N14-O14,-2)) -> 144400 | Q14: =SUMPRODUCT((P14>Paramètres!$B$21:$B$27)*(P14-Paramètres!$B$21:$B$27)*Paramètres!$E$21:$E$27) -> 17359.6 | R14: =Q14*INDEX(Paramètres!$C$31:$C$38,MIN(MAX(INT(N(J14)),0),7)+1) -> 0 | S14: =ROUND(Q14-R14,0) -> 17360 | T14: =ROUND(N($E14)*Paramètres!$C$13,0) -> 8582 | U14: =ROUND(MAX(0,N($E14)-(Q14-R14)-M14)*Paramètres!$C$12,0) -> 2530 | V14: =ROUND(N($E14)-M14-S14-U14,0) -> 250432
B15: 9 | C15: KABRE Esther | D15: 46092 | E15: ='Jan-fév-mars-avril-mai-juin'!H13 -> 135983 | F15: =MIN(ROUNDDOWN(N($E15)*Paramètres!$C$16,0),Paramètres!$D$16) -> 27196 | G15: =MIN(ROUNDDOWN(N($E15)*Paramètres!$C$17,0),Paramètres!$D$17) -> 6799 | H15: =MIN(ROUNDDOWN(N($E15)*Paramètres!$C$18,0),Paramètres!$D$18) -> 6799 | I15: =N($E15)-(F15+G15+H15) -> 95189 | J15: 0 | K15: =IF(I15<Paramètres!$C$11,"Cadre inférieur","Cadre supérieur") -> Cadre inférieur | L15: =MIN(F15,MIN(N($E15)*Paramètres!$C$16,Paramètres!$D$16))+MIN(G15,MIN(N($E15)*Paramètres!$C$17,Paramètres!$D$17))+MIN(H15,MIN(N($E15)*Paramètres!$C$18,Paramètres!$D$18)) -> 40794 | M15: =MIN(N($E15),Paramètres!$C$7)*Paramètres!$C$6 -> 7479.065 | N15: =MIN(M15,I15*Paramètres!$C$8) -> 7479.065 | O15: =I15*IF(K15="Cadre supérieur",Paramètres!$C$10,Paramètres!$C$9) -> 23797.25 | P15: =MAX(0,ROUNDDOWN(N($E15)-L15-N15-O15,-2)) -> 63900 | Q15: =SUMPRODUCT((P15>Paramètres!$B$21:$B$27)*(P15-Paramètres!$B$21:$B$27)*Paramètres!$E$21:$E$27) -> 4352.1 | R15: =Q15*INDEX(Paramètres!$C$31:$C$38,MIN(MAX(INT(N(J15)),0),7)+1) -> 0 | S15: =ROUND(Q15-R15,0) -> 4352 | T15: =ROUND(N($E15)*Paramètres!$C$13,0) -> 4079 | U15: =ROUND(MAX(0,N($E15)-(Q15-R15)-M15)*Paramètres!$C$12,0) -> 1242 | V15: =ROUND(N($E15)-M15-S15-U15,0) -> 122910
B16: Total par mois | E16: =SUM(E7:E15) -> 1977731 | F16: =SUM(F7:F15) -> 395543 | G16: =SUM(G7:G15) -> 98882 | H16: =SUM(H7:H15) -> 98882 | I16: =SUM(I7:I15) -> 1384424 | L16: =SUM(L7:L15) -> 593307 | M16: =SUM(M7:M15) -> 108775.21 | N16: =SUM(N7:N15) -> 108775.21 | O16: =SUM(O7:O15) -> 310277.3 | P16: =SUM(P7:P15) -> 964900 | Q16: =SUM(Q7:Q15) -> 99366.7 | R16: =SUM(R7:R15) -> 0 | S16: =SUM(S7:S15) -> 99367 | ... V16: =SUM(V7:V15) -> 1751894
B17: CUMUL depuis janvier | E17: =Mars!E17+E16 -> 5490965 | S17: =Mars!S17+S16 -> 287685 | T17: =Mars!T17+T16 -> 164729 | U17: =Mars!U17+U16 -> 49013 | V17: =Mars!V17+V16 -> 4852263
C19: Hypothèses du calcul IUTS (modifiables) :
C20: • 0 charge de famille pour tous — colonne « Nb charges » à corriger au besoin.
C21: • Catégorie : salaire de base < 150 000 → cadre inférieur (abattement 25 %) ; sinon cadre supérieur (abattement 20 %).
C22: • Rosalaire = 1 % × (brut − IUTS − CNSS) ; net à payer = brut − CNSS − IUTS − Rosalaire ; TPA = 3 % du brut, à la charge de l'employeur.
C23: • Brut ventilé au maximum exonéré : logement 20 % (≤ 75 000), transport 5 % (≤ 30 000), fonction 5 % (≤ 50 000) du brut ; le reste = salaire de base.
C24: • Taux, plafonds et barème : onglet « Paramètres ». IUTS net arrondi au franc.

Sheet Mai
B4: ETAT DES SALAIRES KS SARL
B5: Période: | D5: MAI 2026 | F5: Ventilation simulée (max. exonéré) | J5: Hypothèses | L5: Calcul IUTS | T5: TPA, Rosalaire et net
B6: N° | C6: Nom&Prénom | D6: DATE D'ENTREE | E6: Brut Mai | F6: Ind. Logement | G6: Ind. Transport | H6: Ind. Fonction | I6: Salaire de base | J6: Nb charges | K6: Catégorie | L6: Montant exonéré | M6: CNSS salarié 5,5 % | N6: Déduction retraite | O6: Abattement forfaitaire | P6: Base imposable (arr. 100) | Q6: IUTS brut | R6: Réduction charges | S6: IUTS NET | T6: TPA 3 % (patronale) | U6: Rosalaire 1 % | V6: SALAIRE NET À PAYER
B7: 1 | C7: OUEDRAOGO Abdoul Ganiyou | D7: 45881 | E7: ='Jan-fév-mars-avril-mai-juin'!I5 -> 225778 | F7: =MIN(ROUNDDOWN(N($E7)*Paramètres!$C$16,0),Paramètres!$D$16) -> 45155 | G7: =MIN(ROUNDDOWN(N($E7)*Paramètres!$C$17,0),Paramètres!$D$17) -> 11288 | H7: =MIN(ROUNDDOWN(N($E7)*Paramètres!$C$18,0),Paramètres!$D$18) -> 11288 | I7: =N($E7)-(F7+G7+H7) -> 158047 | J7: 0 | K7: =IF(I7<Paramètres!$C$11,"Cadre inférieur","Cadre supérieur") -> Cadre supérieur | L7: =MIN(F7,MIN(N($E7)*Paramètres!$C$16,Paramètres!$D$16))+MIN(G7,MIN(N($E7)*Paramètres!$C$17,Paramètres!$D$17))+MIN(H7,MIN(N($E7)*Paramètres!$C$18,Paramètres!$D$18)) -> 67731 | M7: =MIN(N($E7),Paramètres!$C$7)*Paramètres!$C$6 -> 12417.79 | N7: =MIN(M7,I7*Paramètres!$C$8) -> 12417.79 | O7: =I7*IF(K7="Cadre supérieur",Paramètres!$C$10,Paramètres!$C$9) -> 31609.4 | P7: =MAX(0,ROUNDDOWN(N($E7)-L7-N7-O7,-2)) -> 114000 | Q7: =SUMPRODUCT((P7>Paramètres!$B$21:$B$27)*(P7-Paramètres!$B$21:$B$27)*Paramètres!$E$21:$E$27) -> 11928 | R7: =Q7*INDEX(Paramètres!$C$31:$C$38,MIN(MAX(INT(N(J7)),0),7)+1) -> 0 | S7: =ROUND(Q7-R7,0) -> 11928 | T7: =ROUND(N($E7)*Paramètres!$C$13,0) -> 6773 | U7: =ROUND(MAX(0,N($E7)-(Q7-R7)-M7)*Paramètres!$C$12,0) -> 2014 | V7: =ROUND(N($E7)-M7-S7-U7,0) -> 199418
